Workbook
Name LANG: Config!$E$2
Name VATON: Config!$E$3
Name OPENBAL: Dashboard!$N$33
Name MINCASH: Dashboard!$N$34
Name YELLOWF: Dashboard!$N$35
Name START: Dashboard!$N$36
Name VATDAY: Dashboard!$N$38
Name DELAY_ALL: 'Szenario | Scenario'!$J$10
Name SCN_CUSTOMER: 'Szenario | Scenario'!$J$13
Name DELAY_CUSTOMER: 'Szenario | Scenario'!$J$16
Name LOSS_RATE: 'Szenario | Scenario'!$J$19

Sheet Dashboard
N2: =INDEX(Config!$B$6:$C$104,MATCH("ui.language",Config!$A$6:$A$104,0),LANG)
B3: =INDEX(Config!$B$6:$C$104,MATCH("app.title",Config!$A$6:$A$104,0),LANG) | N3: Deutsch
B4: =INDEX(Config!$B$6:$C$104,MATCH("app.sub",Config!$A$6:$A$104,0),LANG)
B7: =INDEX(Config!$B$6:$C$104,MATCH("kpi.balance",Config!$A$6:$A$104,0),LANG) | F7: =INDEX(Config!$B$6:$C$104,MATCH("kpi.recv",Config!$A$6:$A$104,0),LANG) | J7: =INDEX(Config!$B$6:$C$104,MATCH("kpi.low",Config!$A$6:$A$104,0),LANG) | N7: =INDEX(Config!$B$6:$C$104,MATCH("kpi.status",Config!$A$6:$A$104,0),LANG)
B8: =OPENBAL | F8: =SUM('Rechnungen | Invoices'!$Q$9:$Q$108) | J8: =MIN(Config!$V$5:$V$16) | N8: =IF(MAX(Config!$W$5:$W$16)=2,INDEX(Config!$B$6:$C$104,MATCH("status.red",Config!$A$6:$A$104,0),LANG),IF(MAX(Config!$W$5:$W$16)=1,INDEX(Config!$B$6:$C$104,MATCH("status.amber",Config!$A$6:$A$104,0),LANG),INDEX(Config!$B$6:$C$104,MATCH("status.green",Config!$A$6:$A$104,0),LANG)))
B9: =INDEX(Config!$B$6:$C$104,MATCH("kpi.balance.sub",Config!$A$6:$A$104,0),LANG) | F9: =COUNTIF('Rechnungen | Invoices'!$O$9:$O$108,1)&" "&INDEX(Config!$B$6:$C$104,MATCH("kpi.recv.sub",Config!$A$6:$A$104,0),LANG) | J9: =INDEX(Config!$B$6:$C$104,MATCH("kpi.low.sub",Config!$A$6:$A$104,0),LANG) | N9: =INDEX(Config!$B$6:$C$104,MATCH("kpi.status.sub",Config!$A$6:$A$104,0),LANG)
B12: =IF(MAX(Config!$W$5:$W$16)=0,INDEX(Config!$B$6:$C$104,MATCH("alert.green",Config!$A$6:$A$104,0),LANG),IF(MAX(Config!$W$5:$W$16)=2,INDEX(Config!$B$6:$C$104,MATCH("alert.red",Config!$A$6:$A$104,0),LANG),INDEX(Config!$B$6:$C$104,MATCH("alert.amber",Config!$A$6:$A$104,0),LANG))&" "&INDEX(Config!$Y$5:$Y$16,MATCH(MAX(Config!$W$5:$W$16),Config!$W$5:$W$16,0))&".")
B14: =INDEX(Config!$B$6:$C$104,MATCH("sec.chart",Config!$A$6:$A$104,0),LANG)
B31: =INDEX(Config!$B$6:$C$104,MATCH("sec.table",Config!$A$6:$A$104,0),LANG) | J31: =INDEX(Config!$B$6:$C$104,MATCH("sec.settings",Config!$A$6:$A$104,0),LANG)
B32: =INDEX(Config!$B$6:$C$104,MATCH("th.week",Config!$A$6:$A$104,0),LANG) | C32: =INDEX(Config!$B$6:$C$104,MATCH("th.from",Config!$A$6:$A$104,0),LANG) | D32: =INDEX(Config!$B$6:$C$104,MATCH("th.in",Config!$A$6:$A$104,0),LANG) | F32: =INDEX(Config!$B$6:$C$104,MATCH("th.out",Config!$A$6:$A$104,0),LANG) | G32: =INDEX(Config!$B$6:$C$104,MATCH("th.base",Config!$A$6:$A$104,0),LANG) | H32: =INDEX(Config!$B$6:$C$104,MATCH("th.scn",Config!$A$6:$A$104,0),LANG)
B33: =Config!$Y$5 | C33: =Config!$M$5 | D33: =Config!$O$5 | F33: =-Config!$T$5 | G33: =Config!$U$5 | H33: =Config!$V$5 | J33: =INDEX(Config!$B$6:$C$104,MATCH("set.openbal",Config!$A$6:$A$104,0),LANG) | N33: 6800
B34: =Config!$Y$6 | C34: =Config!$M$6 | D34: =Config!$O$6 | F34: =-Config!$T$6 | G34: =Config!$U$6 | H34: =Config!$V$6 | J34: =INDEX(Config!$B$6:$C$104,MATCH("set.mincash",Config!$A$6:$A$104,0),LANG) | N34: 5000
B35: =Config!$Y$7 | C35: =Config!$M$7 | D35: =Config!$O$7 | F35: =-Config!$T$7 | G35: =Config!$U$7 | H35: =Config!$V$7 | J35: =INDEX(Config!$B$6:$C$104,MATCH("set.yellow",Config!$A$6:$A$104,0),LANG) | N35: 1.5
B36: =Config!$Y$8 | C36: =Config!$M$8 | D36: =Config!$O$8 | F36: =-Config!$T$8 | G36: =Config!$U$8 | H36: =Config!$V$8 | J36: =INDEX(Config!$B$6:$C$104,MATCH("set.start",Config!$A$6:$A$104,0),LANG) | N36: =TODAY()-WEEKDAY(TODAY(),3)
B37: =Config!$Y$9 | C37: =Config!$M$9 | D37: =Config!$O$9 | F37: =-Config!$T$9 | G37: =Config!$U$9 | H37: =Config!$V$9 | J37: =INDEX(Config!$B$6:$C$104,MATCH("set.vat",Config!$A$6:$A$104,0),LANG) | N37: =Config!$H$9
B38: =Config!$Y$10 | C38: =Config!$M$10 | D38: =Config!$O$10 | F38: =-Config!$T$10 | G38: =Config!$U$10 | H38: =Config!$V$10 | J38: =INDEX(Config!$B$6:$C$104,MATCH("set.vatday",Config!$A$6:$A$104,0),LANG) | N38: 10
B39: =Config!$Y$11 | C39: =Config!$M$11 | D39: =Config!$O$11 | F39: =-Config!$T$11 | G39: =Config!$U$11 | H39: =Config!$V$11 | J39: =INDEX(Config!$B$6:$C$104,MATCH("set.hint",Config!$A$6:$A$104,0),LANG)
B40: =Config!$Y$12 | C40: =Config!$M$12 | D40: =Config!$O$12 | F40: =-Config!$T$12 | G40: =Config!$U$12 | H40: =Config!$V$12
B41: =Config!$Y$13 | C41: =Config!$M$13 | D41: =Config!$O$13 | F41: =-Config!$T$13 | G41: =Config!$U$13 | H41: =Config!$V$13
B42: =Config!$Y$14 | C42: =Config!$M$14 | D42: =Config!$O$14 | F42: =-Config!$T$14 | G42: =Config!$U$14 | H42: =Config!$V$14
B43: =Config!$Y$15 | C43: =Config!$M$15 | D43: =Config!$O$15 | F43: =-Config!$T$15 | G43: =Config!$U$15 | H43: =Config!$V$15
B44: =Config!$Y$16 | C44: =Config!$M$16 | D44: =Config!$O$16 | F44: =-Config!$T$16 | G44: =Config!$U$16 | H44: =Config!$V$16
B46: =INDEX(Config!$B$6:$C$104,MATCH("sec.help",Config!$A$6:$A$104,0),LANG)
B48: =INDEX(Config!$B$6:$C$104,MATCH("help.1",Config!$A$6:$A$104,0),LANG)
B49: =INDEX(Config!$B$6:$C$104,MATCH("help.2",Config!$A$6:$A$104,0),LANG)
B50: =INDEX(Config!$B$6:$C$104,MATCH("help.3",Config!$A$6:$A$104,0),LANG)
B51: =INDEX(Config!$B$6:$C$104,MATCH("help.4",Config!$A$6:$A$104,0),LANG)
B52: =INDEX(Config!$B$6:$C$104,MATCH("help.5",Config!$A$6:$A$104,0),LANG)
B53: =INDEX(Config!$B$6:$C$104,MATCH("foot.note",Config!$A$6:$A$104,0),LANG)

Sheet Rechnungen | Invoices
B3: =INDEX(Config!$B$6:$C$104,MATCH("app.title",Config!$A$6:$A$104,0),LANG)
B4: =INDEX(Config!$B$6:$C$104,MATCH("inv.title",Config!$A$6:$A$104,0),LANG)
B6: =INDEX(Config!$B$6:$C$104,MATCH("inv.title",Config!$A$6:$A$104,0),LANG)
B7: =INDEX(Config!$B$6:$C$104,MATCH("inv.hint",Config!$A$6:$A$104,0),LANG)
B8: =INDEX(Config!$B$6:$C$104,MATCH("inv.h.no",Config!$A$6:$A$104,0),LANG) | C8: =INDEX(Config!$B$6:$C$104,MATCH("inv.h.customer",Config!$A$6:$A$104,0),LANG) | D8: =INDEX(Config!$B$6:$C$104,MATCH("inv.h.invno",Config!$A$6:$A$104,0),LANG) | E8: =INDEX(Config!$B$6:$C$104,MATCH("inv.h.amount",Config!$A$6:$A$104,0),LANG) | F8: =INDEX(Config!$B$6:$C$104,MATCH("inv.h.vat",Config!$A$6:$A$104,0),LANG) | G8: =INDEX(Config!$B$6:$C$104,MATCH("inv.h.gross",Config!$A$6:$A$104,0),LANG) | H8: =INDEX(Config!$B$6:$C$104,MATCH("inv.h.date",Config!$A$6:$A$104,0),LANG) | I8: =INDEX(Config!$B$6:$C$104,MATCH("inv.h.terms",Config!$A$6:$A$104,0),LANG) | J8: =INDEX(Config!$B$6:$C$104,MATCH("inv.h.due",Config!$A$6:$A$104,0),LANG) | K8: =INDEX(Config!$B$6:$C$104,MATCH("inv.h.status",Config!$A$6:$A$104,0),LANG) | L8: =INDEX(Config!$B$6:$C$104,MATCH("inv.h.expdate",Config!$A$6:$A$104,0),LANG) | M8: =INDEX(Config!$B$6:$C$104,MATCH("inv.h.expamt",Config!$A$6:$A$104,0),LANG)
B9: 1 | C9: Meier & Partner GmbH | D9: RE-2601 | E9: 1850 | F9: =IF(VATON=1,0.19,"") | G9: =IF($E9="","",$E9*(1+IF(VATON=1,N($F9),0))) | H9: =TODAY()-38 | I9: 30 | J9: =IF($H9="","",$H9+N($I9)) | K9: =Config!$H$5 | L9: =IF($O9=0,"",MAX($J9,START)+DELAY_ALL+IF($C9=SCN_CUSTOMER,DELAY_CUSTOMER,0)) | M9: =IF($O9=0,"",$S9) | O9: =IF($K9="",0,IF(COUNTIF(Config!$F$5:$G$5,$K9)>0,1,0)) | P9: =IF($E9="",0,IF(VATON=1,$E9*N($F9),0)) | Q9: =IF($O9=0,0,N($G9)) | R9: =IF($O9=0,"",MAX($J9,START)) | S9: =IF($O9=0,0,N($G9)*(1-IF($C9=SCN_CUSTOMER,LOSS_RATE,0)))
B10: 2 | C10: Stadtwerke Lindau | D10: RE-2602 | E10: 780 | F10: =IF(VATON=1,0.19,"") | G10: =IF($E10="","",$E10*(1+IF(VATON=1,N($F10),0))) | H10: =TODAY()-31 | I10: 14 | J10: =IF($H10="","",$H10+N($I10)) | K10: =Config!$H$5 | L10: =IF($O10=0,"",MAX($J10,START)+DELAY_ALL+IF($C10=SCN_CUSTOMER,DELAY_CUSTOMER,0)) | M10: =IF($O10=0,"",$S10) | O10: =IF($K10="",0,IF(COUNTIF(Config!$F$5:$G$5,$K10)>0,1,0)) | P10: =IF($E10="",0,IF(VATON=1,$E10*N($F10),0)) | Q10: =IF($O10=0,0,N($G10)) | R10: =IF($O10=0,"",MAX($J10,START)) | S10: =IF($O10=0,0,N($G10)*(1-IF($C10=SCN_CUSTOMER,LOSS_RATE,0)))
B11: 3 | C11: Kreativagentur Nord | D11: RE-2603 | E11: 1240 | F11: =IF(VATON=1,0.19,"") | G11: =IF($E11="","",$E11*(1+IF(VATON=1,N($F11),0))) | H11: =TODAY()-22 | I11: 30 | J11: =IF($H11="","",$H11+N($I11)) | K11: =Config!$H$5 | L11: =IF($O11=0,"",MAX($J11,START)+DELAY_ALL+IF($C11=SCN_CUSTOMER,DELAY_CUSTOMER,0)) | M11: =IF($O11=0,"",$S11) | O11: =IF($K11="",0,IF(COUNTIF(Config!$F$5:$G$5,$K11)>0,1,0)) | P11: =IF($E11="",0,IF(VATON=1,$E11*N($F11),0)) | Q11: =IF($O11=0,0,N($G11)) | R11: =IF($O11=0,"",MAX($J11,START)) | S11: =IF($O11=0,0,N($G11)*(1-IF($C11=SCN_CUSTOMER,LOSS_RATE,0)))
B12: 4 | C12: Bauer Consulting KG | D12: RE-2604 | E12: 4500 | F12: =IF(VATON=1,0.19,"") | G12: =IF($E12="","",$E12*(1+IF(VATON=1,N($F12),0))) | H12: =TODAY()-18 | I12: 45 | J12: =IF($H12="","",$H12+N($I12)) | K12: =Config!$H$5 | L12: =IF($O12=0,"",MAX($J12,START)+DELAY_ALL+IF($C12=SCN_CUSTOMER,DELAY_CUSTOMER,0)) | M12: =IF($O12=0,"",$S12) | O12: =IF($K12="",0,IF(COUNTIF(Config!$F$5:$G$5,$K12)>0,1,0)) | P12: =IF($E12="",0,IF(VATON=1,$E12*N($F12),0)) | Q12: =IF($O12=0,0,N($G12)) | R12: =IF($O12=0,"",MAX($J12,START)) | S12: =IF($O12=0,0,N($G12)*(1-IF($C12=SCN_CUSTOMER,LOSS_RATE,0)))
B13: 5 | C13: Hotel Seeblick | D13: RE-2605 | E13: 640 | F13: =IF(VATON=1,0.19,"") | G13: =IF($E13="","",$E13*(1+IF(VATON=1,N($F13),0))) | H13: =TODAY()-14 | I13: 14 | J13: =IF($H13="","",$H13+N($I13)) | K13: =Config!$H$5 | L13: =IF($O13=0,"",MAX($J13,START)+DELAY_ALL+IF($C13=SCN_CUSTOMER,DELAY_CUSTOMER,0)) | M13: =IF($O13=0,"",$S13) | O13: =IF($K13="",0,IF(COUNTIF(Config!$F$5:$G$5,$K13)>0,1,0)) | P13: =IF($E13="",0,IF(VATON=1,$E13*N($F13),0)) | Q13: =IF($O13=0,0,N($G13)) | R13: =IF($O13=0,"",MAX($J13,START)) | S13: =IF($O13=0,0,N($G13)*(1-IF($C13=SCN_CUSTOMER,LOSS_RATE,0)))
B14: 6 | C14: TechnoPlus AG | D14: RE-2606 | E14: 8400 | F14: =IF(VATON=1,0.19,"") | G14: =IF($E14="","",$E14*(1+IF(VATON=1,N($F14),0))) | H14: =TODAY()-11 | I14: 60 | J14: =IF($H14="","",$H14+N($I14)) | K14: =Config!$H$5 | L14: =IF($O14=0,"",MAX($J14,START)+DELAY_ALL+IF($C14=SCN_CUSTOMER,DELAY_CUSTOMER,0)) | M14: =IF($O14=0,"",$S14) | O14: =IF($K14="",0,IF(COUNTIF(Config!$F$5:$G$5,$K14)>0,1,0)) | P14: =IF($E14="",0,IF(VATON=1,$E14*N($F14),0)) | Q14: =IF($O14=0,0,N($G14)) | R14: =IF($O14=0,"",MAX($J14,START)) | S14: =IF($O14=0,0,N($G14)*(1-IF($C14=SCN_CUSTOMER,LOSS_RATE,0)))
B15: 7 | C15: Praxis Dr. Winter | D15: RE-2607 | E15: 980 | F15: =IF(VATON=1,0.19,"") | G15: =IF($E15="","",$E15*(1+IF(VATON=1,N($F15),0))) | H15: =TODAY()-9 | I15: 30 | J15: =IF($H15="","",$H15+N($I15)) | K15: =Config!$H$5 | L15: =IF($O15=0,"",MAX($J15,START)+DELAY_ALL+IF($C15=SCN_CUSTOMER,DELAY_CUSTOMER,0)) | M15: =IF($O15=0,"",$S15) | O15: =IF($K15="",0,IF(COUNTIF(Config!$F$5:$G$5,$K15)>0,1,0)) | P15: =IF($E15="",0,IF(VATON=1,$E15*N($F15),0)) | Q15: =IF($O15=0,0,N($G15)) | R15: =IF($O15=0,"",MAX($J15,START)) | S15: =IF($O15=0,0,N($G15)*(1-IF($C15=SCN_CUSTOMER,LOSS_RATE,0)))
B16: 8 | C16: Grünfeld Landschaftsbau | D16: RE-2608 | E16: 1150 | F16: =IF(VATON=1,0.19,"") | G16: =IF($E16="","",$E16*(1+IF(VATON=1,N($F16),0))) | H16: =TODAY()-6 | I16: 21 | J16: =IF($H16="","",$H16+N($I16)) | K16: =Config!$H$5 | L16: =IF($O16=0,"",MAX($J16,START)+DELAY_ALL+IF($C16=SCN_CUSTOMER,DELAY_CUSTOMER,0)) | M16: =IF($O16=0,"",$S16) | O16: =IF($K16="",0,IF(COUNTIF(Config!$F$5:$G$5,$K16)>0,1,0)) | P16: =IF($E16="",0,IF(VATON=1,$E16*N($F16),0)) | Q16: =IF($O16=0,0,N($G16)) | R16: =IF($O16=0,"",MAX($J16,START)) | S16: =IF($O16=0,0,N($G16)*(1-IF($C16=SCN_CUSTOMER,LOSS_RATE,0)))
B17: 9 | C17: Meier & Partner GmbH | D17: RE-2609 | E17: 2600 | F17: =IF(VATON=1,0.19,"") | G17: =IF($E17="","",$E17*(1+IF(VATON=1,N($F17),0))) | H17: =TODAY()-3 | I17: 30 | J17: =IF($H17="","",$H17+N($I17)) | K17: =Config!$H$5 | L17: =IF($O17=0,"",MAX($J17,START)+DELAY_ALL+IF($C17=SCN_CUSTOMER,DELAY_CUSTOMER,0)) | M17: =IF($O17=0,"",$S17) | O17: =IF($K17="",0,IF(COUNTIF(Config!$F$5:$G$5,$K17)>0,1,0)) | P17: =IF($E17="",0,IF(VATON=1,$E17*N($F17),0)) | Q17: =IF($O17=0,0,N($G17)) | R17: =IF($O17=0,"",MAX($J17,START)) | S17: =IF($O17=0,0,N($G17)*(1-IF($C17=SCN_CUSTOMER,LOSS_RATE,0)))
B18: 10 | C18: Café Sonnenblume | D18: RE-2610 | E18: 520 | F18: =IF(VATON=1,0.19,"") | G18: =IF($E18="","",$E18*(1+IF(VATON=1,N($F18),0))) | H18: =TODAY()+1 | I18: 14 | J18: =IF($H18="","",$H18+N($I18)) | K18: =Config!$H$5 | L18: =IF($O18=0,"",MAX($J18,START)+DELAY_ALL+IF($C18=SCN_CUSTOMER,DELAY_CUSTOMER,0)) | M18: =IF($O18=0,"",$S18) | O18: =IF($K18="",0,IF(COUNTIF(Config!$F$5:$G$5,$K18)>0,1,0)) | P18: =IF($E18="",0,IF(VATON=1,$E18*N($F18),0)) | Q18: =IF($O18=0,0,N($G18)) | R18: =IF($O18=0,"",MAX($J18,START)) | S18: =IF($O18=0,0,N($G18)*(1-IF($C18=SCN_CUSTOMER,LOSS_RATE,0)))
B19: 11 | C19: TechnoPlus AG | D19: RE-2611 | E19: 5200 | F19: =IF(VATON=1,0.19,"") | G19: =IF($E19="","",$E19*(1+IF(VATON=1,N($F19),0))) | H19: =TODAY()+4 | I19: 45 | J19: =IF($H19="","",$H19+N($I19)) | K19: =Config!$H$5 | L19: =IF($O19=0,"",MAX($J19,START)+DELAY_ALL+IF($C19=SCN_CUSTOMER,DELAY_CUSTOMER,0)) | M19: =IF($O19=0,"",$S19) | O19: =IF($K19="",0,IF(COUNTIF(Config!$F$5:$G$5,$K19)>0,1,0)) | P19: =IF($E19="",0,IF(VATON=1,$E19*N($F19),0)) | Q19: =IF($O19=0,0,N($G19)) | R19: =IF($O19=0,"",MAX($J19,START)) | S19: =IF($O19=0,0,N($G19)*(1-IF($C19=SCN_CUSTOMER,LOSS_RATE,0)))
B20: 12 | C20: Schmidt Immobilien | D20: RE-2612 | E20: 3100 | F20: =IF(VATON=1,0.19,"") | G20: =IF($E20="","",$E20*(1+IF(VATON=1,N($F20),0))) | H20: =TODAY()+8 | I20: 30 | J20: =IF($H20="","",$H20+N($I20)) | K20: =Config!$H$5 | L20: =IF($O20=0,"",MAX($J20,START)+DELAY_ALL+IF($C20=SCN_CUSTOMER,DELAY_CUSTOMER,0)) | M20: =IF($O20=0,"",$S20) | O20: =IF($K20="",0,IF(COUNTIF(Config!$F$5:$G$5,$K20)>0,1,0)) | P20: =IF($E20="",0,IF(VATON=1,$E20*N($F20),0)) | Q20: =IF($O20=0,0,N($G20)) | R20: =IF($O20=0,"",MAX($J20,START)) | S20: =IF($O20=0,0,N($G20)*(1-IF($C20=SCN_CUSTOMER,LOSS_RATE,0)))
B21: 13 | C21: Kreativagentur Nord | D21: RE-2598 | E21: 1450 | F21: =IF(VATON=1,0.19,"") | G21: =IF($E21="","",$E21*(1+IF(VATON=1,N($F21),0))) | H21: =TODAY()-52 | I21: 30 | J21: =IF($H21="","",$H21+N($I21)) | K21: =Config!$H$6 | L21: =IF($O21=0,"",MAX($J21,START)+DELAY_ALL+IF($C21=SCN_CUSTOMER,DELAY_CUSTOMER,0)) | M21: =IF($O21=0,"",$S21) | O21: =IF($K21="",0,IF(COUNTIF(Config!$F$5:$G$5,$K21)>0,1,0)) | P21: =IF($E21="",0,IF(VATON=1,$E21*N($F21),0)) | Q21: =IF($O21=0,0,N($G21)) | R21: =IF($O21=0,"",MAX($J21,START)) | S21: =IF($O21=0,0,N($G21)*(1-IF($C21=SCN_CUSTOMER,LOSS_RATE,0)))
B22: 14 | C22: Hotel Seeblick | D22: RE-2596 | E22: 780 | F22: =IF(VATON=1,0.19,"") | G22: =IF($E22="","",$E22*(1+IF(VATON=1,N($F22),0))) | H22: =TODAY()-58 | I22: 14 | J22: =IF($H22="","",$H22+N($I22)) | K22: =Config!$H$6 | L22: =IF($O22=0,"",MAX($J22,START)+DELAY_ALL+IF($C22=SCN_CUSTOMER,DELAY_CUSTOMER,0)) | M22: =IF($O22=0,"",$S22) | O22: =IF($K22="",0,IF(COUNTIF(Config!$F$5:$G$5,$K22)>0,1,0)) | P22: =IF($E22="",0,IF(VATON=1,$E22*N($F22),0)) | Q22: =IF($O22=0,0,N($G22)) | R22: =IF($O22=0,"",MAX($J22,START)) | S22: =IF($O22=0,0,N($G22)*(1-IF($C22=SCN_CUSTOMER,LOSS_RATE,0)))
B23: 15 | C23: Bauer Consulting KG | D23: RE-2594 | E23: 3200 | F23: =IF(VATON=1,0.19,"") | G23: =IF($E23="","",$E23*(1+IF(VATON=1,N($F23),0))) | H23: =TODAY()-66 | I23: 30 | J23: =IF($H23="","",$H23+N($I23)) | K23: =Config!$H$6 | L23: =IF($O23=0,"",MAX($J23,START)+DELAY_ALL+IF($C23=SCN_CUSTOMER,DELAY_CUSTOMER,0)) | M23: =IF($O23=0,"",$S23) | O23: =IF($K23="",0,IF(COUNTIF(Config!$F$5:$G$5,$K23)>0,1,0)) | P23: =IF($E23="",0,IF(VATON=1,$E23*N($F23),0)) | Q23: =IF($O23=0,0,N($G23)) | R23: =IF($O23=0,"",MAX($J23,START)) | S23: =IF($O23=0,0,N($G23)*(1-IF($C23=SCN_CUSTOMER,LOSS_RATE,0)))
B24: 16 | G24: =IF($E24="","",$E24*(1+IF(VATON=1,N($F24),0))) | J24: =IF($H24="","",$H24+N($I24)) | L24: =IF($O24=0,"",MAX($J24,START)+DELAY_ALL+IF($C24=SCN_CUSTOMER,DELAY_CUSTOMER,0)) | M24: =IF($O24=0,"",$S24) | O24: =IF($K24="",0,IF(COUNTIF(Config!$F$5:$G$5,$K24)>0,1,0)) | P24: =IF($E24="",0,IF(VATON=1,$E24*N($F24),0)) | Q24: =IF($O24=0,0,N($G24)) | R24: =IF($O24=0,"",MAX($J24,START)) | S24: =IF($O24=0,0,N($G24)*(1-IF($C24=SCN_CUSTOMER,LOSS_RATE,0)))
B25: 17 | G25: =IF($E25="","",$E25*(1+IF(VATON=1,N($F25),0))) | J25: =IF($H25="","",$H25+N($I25)) | L25: =IF($O25=0,"",MAX($J25,START)+DELAY_ALL+IF($C25=SCN_CUSTOMER,DELAY_CUSTOMER,0)) | M25: =IF($O25=0,"",$S25) | O25: =IF($K25="",0,IF(COUNTIF(Config!$F$5:$G$5,$K25)>0,1,0)) | P25: =IF($E25="",0,IF(VATON=1,$E25*N($F25),0)) | Q25: =IF($O25=0,0,N($G25)) | R25: =IF($O25=0,"",MAX($J25,START)) | S25: =IF($O25=0,0,N($G25)*(1-IF($C25=SCN_CUSTOMER,LOSS_RATE,0)))
B26: 18 | G26: =IF($E26="","",$E26*(1+IF(VATON=1,N($F26),0))) | J26: =IF($H26="","",$H26+N($I26)) | L26: =IF($O26=0,"",MAX($J26,START)+DELAY_ALL+IF($C26=SCN_CUSTOMER,DELAY_CUSTOMER,0)) | M26: =IF($O26=0,"",$S26) | O26: =IF($K26="",0,IF(COUNTIF(Config!$F$5:$G$5,$K26)>0,1,0)) | P26: =IF($E26="",0,IF(VATON=1,$E26*N($F26),0)) | Q26: =IF($O26=0,0,N($G26)) | R26: =IF($O26=0,"",MAX($J26,START)) | S26: =IF($O26=0,0,N($G26)*(1-IF($C26=SCN_CUSTOMER,LOSS_RATE,0)))
B27: 19 | G27: =IF($E27="","",$E27*(1+IF(VATON=1,N($F27),0))) | J27: =IF($H27="","",$H27+N($I27)) | L27: =IF($O27=0,"",MAX($J27,START)+DELAY_ALL+IF($C27=SCN_CUSTOMER,DELAY_CUSTOMER,0)) | M27: =IF($O27=0,"",$S27) | O27: =IF($K27="",0,IF(COUNTIF(Config!$F$5:$G$5,$K27)>0,1,0)) | P27: =IF($E27="",0,IF(VATON=1,$E27*N($F27),0)) | Q27: =IF($O27=0,0,N($G27)) | R27: =IF($O27=0,"",MAX($J27,START)) | S27: =IF($O27=0,0,N($G27)*(1-IF($C27=SCN_CUSTOMER,LOSS_RATE,0)))
B28: 20 | G28: =IF($E28="","",$E28*(1+IF(VATON=1,N($F28),0))) | J28: =IF($H28="","",$H28+N($I28)) | L28: =IF($O28=0,"",MAX($J28,START)+DELAY_ALL+IF($C28=SCN_CUSTOMER,DELAY_CUSTOMER,0)) | M28: =IF($O28=0,"",$S28) | O28: =IF($K28="",0,IF(COUNTIF(Config!$F$5:$G$5,$K28)>0,1,0)) | P28: =IF($E28="",0,IF(VATON=1,$E28*N($F28),0)) | Q28: =IF($O28=0,0,N($G28)) | R28: =IF($O28=0,"",MAX($J28,START)) | S28: =IF($O28=0,0,N($G28)*(1-IF($C28=SCN_CUSTOMER,LOSS_RATE,0)))
B29: 21 | G29: =IF($E29="","",$E29*(1+IF(VATON=1,N($F29),0))) | J29: =IF($H29="","",$H29+N($I29)) | L29: =IF($O29=0,"",MAX($J29,START)+DELAY_ALL+IF($C29=SCN_CUSTOMER,DELAY_CUSTOMER,0)) | M29: =IF($O29=0,"",$S29) | O29: =IF($K29="",0,IF(COUNTIF(Config!$F$5:$G$5,$K29)>0,1,0)) | P29: =IF($E29="",0,IF(VATON=1,$E29*N($F29),0)) | Q29: =IF($O29=0,0,N($G29)) | R29: =IF($O29=0,"",MAX($J29,START)) | S29: =IF($O29=0,0,N($G29)*(1-IF($C29=SCN_CUSTOMER,LOSS_RATE,0)))
B30: 22 | G30: =IF($E30="","",$E30*(1+IF(VATON=1,N($F30),0))) | J30: =IF($H30="","",$H30+N($I30)) | L30: =IF($O30=0,"",MAX($J30,START)+DELAY_ALL+IF($C30=SCN_CUSTOMER,DELAY_CUSTOMER,0)) | M30: =IF($O30=0,"",$S30) | O30: =IF($K30="",0,IF(COUNTIF(Config!$F$5:$G$5,$K30)>0,1,0)) | P30: =IF($E30="",0,IF(VATON=1,$E30*N($F30),0)) | Q30: =IF($O30=0,0,N($G30)) | R30: =IF($O30=0,"",MAX($J30,START)) | S30: =IF($O30=0,0,N($G30)*(1-IF($C30=SCN_CUSTOMER,LOSS_RATE,0)))
B31: 23 | G31: =IF($E31="","",$E31*(1+IF(VATON=1,N($F31),0))) | J31: =IF($H31="","",$H31+N($I31)) | L31: =IF($O31=0,"",MAX($J31,START)+DELAY_ALL+IF($C31=SCN_CUSTOMER,DELAY_CUSTOMER,0)) | M31: =IF($O31=0,"",$S31) | O31: =IF($K31="",0,IF(COUNTIF(Config!$F$5:$G$5,$K31)>0,1,0)) | P31: =IF($E31="",0,IF(VATON=1,$E31*N($F31),0)) | Q31: =IF($O31=0,0,N($G31)) | R31: =IF($O31=0,"",MAX($J31,START)) | S31: =IF($O31=0,0,N($G31)*(1-IF($C31=SCN_CUSTOMER,LOSS_RATE,0)))
B32: 24 | G32: =IF($E32="","",$E32*(1+IF(VATON=1,N($F32),0))) | J32: =IF($H32="","",$H32+N($I32)) | L32: =IF($O32=0,"",MAX($J32,START)+DELAY_ALL+IF($C32=SCN_CUSTOMER,DELAY_CUSTOMER,0)) | M32: =IF($O32=0,"",$S32) | O32: =IF($K32="",0,IF(COUNTIF(Config!$F$5:$G$5,$K32)>0,1,0)) | P32: =IF($E32="",0,IF(VATON=1,$E32*N($F32),0)) | Q32: =IF($O32=0,0,N($G32)) | R32: =IF($O32=0,"",MAX($J32,START)) | S32: =IF($O32=0,0,N($G32)*(1-IF($C32=SCN_CUSTOMER,LOSS_RATE,0)))
B33: 25 | G33: =IF($E33="","",$E33*(1+IF(VATON=1,N($F33),0))) | J33: =IF($H33="","",$H33+N($I33)) | L33: =IF($O33=0,"",MAX($J33,START)+DELAY_ALL+IF($C33=SCN_CUSTOMER,DELAY_CUSTOMER,0)) | M33: =IF($O33=0,"",$S33) | O33: =IF($K33="",0,IF(COUNTIF(Config!$F$5:$G$5,$K33)>0,1,0)) | P33: =IF($E33="",0,IF(VATON=1,$E33*N($F33),0)) | Q33: =IF($O33=0,0,N($G33)) | R33: =IF($O33=0,"",MAX($J33,START)) | S33: =IF($O33=0,0,N($G33)*(1-IF($C33=SCN_CUSTOMER,LOSS_RATE,0)))
B34: 26 | G34: =IF($E34="","",$E34*(1+IF(VATON=1,N($F34),0))) | J34: =IF($H34="","",$H34+N($I34)) | L34: =IF($O34=0,"",MAX($J34,START)+DELAY_ALL+IF($C34=SCN_CUSTOMER,DELAY_CUSTOMER,0)) | M34: =IF($O34=0,"",$S34) | O34: =IF($K34="",0,IF(COUNTIF(Config!$F$5:$G$5,$K34)>0,1,0)) | P34: =IF($E34="",0,IF(VATON=1,$E34*N($F34),0)) | Q34: =IF($O34=0,0,N($G34)) | R34: =IF($O34=0,"",MAX($J34,START)) | S34: =IF($O34=0,0,N($G34)*(1-IF($C34=SCN_CUSTOMER,LOSS_RATE,0)))
B35: 27 | G35: =IF($E35="","",$E35*(1+IF(VATON=1,N($F35),0))) | J35: =IF($H35="","",$H35+N($I35)) | L35: =IF($O35=0,"",MAX($J35,START)+DELAY_ALL+IF($C35=SCN_CUSTOMER,DELAY_CUSTOMER,0)) | M35: =IF($O35=0,"",$S35) | O35: =IF($K35="",0,IF(COUNTIF(Config!$F$5:$G$5,$K35)>0,1,0)) | P35: =IF($E35="",0,IF(VATON=1,$E35*N($F35),0)) | Q35: =IF($O35=0,0,N($G35)) | R35: =IF($O35=0,"",MAX($J35,START)) | S35: =IF($O35=0,0,N($G35)*(1-IF($C35=SCN_CUSTOMER,LOSS_RATE,0)))
... B108: 100 | G108: =IF($E108="","",$E108*(1+IF(VATON=1,N($F108),0))) | J108: =IF($H108="","",$H108+N($I108)) | L108: =IF($O108=0,"",MAX($J108,START)+DELAY_ALL+IF($C108=SCN_CUSTOMER,DELAY_CUSTOMER,0)) | M108: =IF($O108=0,"",$S108) | O108: =IF($K108="",0,IF(COUNTIF(Config!$F$5:$G$5,$K108)>0,1,0)) | P108: =IF($E108="",0,IF(VATON=1,$E108*N($F108),0)) | Q108: =IF($O108=0,0,N($G108)) | R108: =IF($O108=0,"",MAX($J108,START)) | S108: =IF($O108=0,0,N($G108)*(1-IF($C108=SCN_CUSTOMER,LOSS_RATE,0)))
B109: =INDEX(Config!$B$6:$C$104,MATCH("inv.total",Config!$A$6:$A$104,0),LANG) | G109: =SUM($Q$9:$Q$108) | L109: =SUM($S$9:$S$108)
B111: =INDEX(Config!$B$6:$C$104,MATCH("inv.scnnote",Config!$A$6:$A$104,0),LANG)

Sheet Kosten | Costs
B3: =INDEX(Config!$B$6:$C$104,MATCH("app.title",Config!$A$6:$A$104,0),LANG)
B4: =INDEX(Config!$B$6:$C$104,MATCH("cost.title",Config!$A$6:$A$104,0),LANG)
B6: =INDEX(Config!$B$6:$C$104,MATCH("cost.fixed",Config!$A$6:$A$104,0),LANG)
B7: =INDEX(Config!$B$6:$C$104,MATCH("cost.fixed.hint",Config!$A$6:$A$104,0),LANG)
B8: =INDEX(Config!$B$6:$C$104,MATCH("cost.h.name",Config!$A$6:$A$104,0),LANG) | C8: =INDEX(Config!$B$6:$C$104,MATCH("cost.h.cat",Config!$A$6:$A$104,0),LANG) | D8: =INDEX(Config!$B$6:$C$104,MATCH("cost.h.month",Config!$A$6:$A$104,0),LANG) | E8: =INDEX(Config!$B$6:$C$104,MATCH("cost.h.day",Config!$A$6:$A$104,0),LANG)
B9: Miete Büro / Office rent | C9: Raumkosten / Premises | D9: 850 | E9: 1
B10: Krankenversicherung / Health insurance | C10: Vorsorge / Insurance | D10: 780 | E10: 1
B11: Altersvorsorge / Pension plan | C11: Vorsorge / Insurance | D11: 300 | E11: 1
B12: Leasing Fahrzeug / Car leasing | C12: Fahrzeug / Vehicle | D12: 320 | E12: 5
B13: Software-Abos / Software subscriptions | C13: IT / IT | D13: 165 | E13: 10
B14: Betriebshaftpflicht / Liability cover | C14: Vorsorge / Insurance | D14: 95 | E14: 12
B15: Telefon & Internet / Phone & internet | C15: IT / IT | D15: 75 | E15: 15
B16: Steuerberatung / Tax adviser | C16: Beratung / Advisory | D16: 180 | E16: 20
B17: Buchhaltungstool / Accounting tool | C17: IT / IT | D17: 39 | E17: 25
B29: =INDEX(Config!$B$6:$C$104,MATCH("cost.sum.fixed",Config!$A$6:$A$104,0),LANG) | D29: =SUM(D9:D28)
B31: =INDEX(Config!$B$6:$C$104,MATCH("cost.var",Config!$A$6:$A$104,0),LANG)
B32: =INDEX(Config!$B$6:$C$104,MATCH("cost.var.hint",Config!$A$6:$A$104,0),LANG)
B33: =INDEX(Config!$B$6:$C$104,MATCH("cost.h.name",Config!$A$6:$A$104,0),LANG) | C33: =INDEX(Config!$B$6:$C$104,MATCH("cost.h.cat",Config!$A$6:$A$104,0),LANG) | D33: =INDEX(Config!$B$6:$C$104,MATCH("cost.h.amount",Config!$A$6:$A$104,0),LANG) | E33: =INDEX(Config!$B$6:$C$104,MATCH("cost.h.date",Config!$A$6:$A$104,0),LANG)
B34: Reisekosten Kundentermin / Client travel | C34: Reisen / Travel | D34: 430 | E34: =TODAY()+9
B35: Steuervorauszahlung / Tax prepayment | C35: Steuern / Taxes | D35: 3200 | E35: =TODAY()+12
B36: Weiterbildung Seminar / Training seminar | C36: Personal / People | D36: 890 | E36: =TODAY()+17
B37: Neue Hardware / New hardware | C37: IT / IT | D37: 1950 | E37: =TODAY()+26
B38: Marketing-Kampagne / Marketing campaign | C38: Marketing / Marketing | D38: 1250 | E38: =TODAY()+38
B39: Messeauftritt / Trade fair booth | C39: Marketing / Marketing | D39: 2650 | E39: =TODAY()+58
B64: =INDEX(Config!$B$6:$C$104,MATCH("cost.sum.var",Config!$A$6:$A$104,0),LANG) | D64: =SUM(D34:D63)

Sheet Szenario | Scenario
B3: =INDEX(Config!$B$6:$C$104,MATCH("app.title",Config!$A$6:$A$104,0),LANG)
B4: =INDEX(Config!$B$6:$C$104,MATCH("scn.title",Config!$A$6:$A$104,0),LANG)
B6: =INDEX(Config!$B$6:$C$104,MATCH("scn.controls",Config!$A$6:$A$104,0),LANG)
B7: =INDEX(Config!$B$6:$C$104,MATCH("scn.hint",Config!$A$6:$A$104,0),LANG)
C10: =INDEX(Config!$B$6:$C$104,MATCH("scn.delay_all",Config!$A$6:$A$104,0),LANG) | J10: 14 | N10: =INDEX(Config!$B$6:$C$104,MATCH("scn.days",Config!$A$6:$A$104,0),LANG)
C11: =INDEX(Config!$B$6:$C$104,MATCH("scn.delay_all.h",Config!$A$6:$A$104,0),LANG)
C13: =INDEX(Config!$B$6:$C$104,MATCH("scn.customer",Config!$A$6:$A$104,0),LANG) | J13: TechnoPlus AG
C14: =INDEX(Config!$B$6:$C$104,MATCH("scn.customer.h",Config!$A$6:$A$104,0),LANG)
C16: =INDEX(Config!$B$6:$C$104,MATCH("scn.delay_cust",Config!$A$6:$A$104,0),LANG) | J16: 21 | N16: =INDEX(Config!$B$6:$C$104,MATCH("scn.days",Config!$A$6:$A$104,0),LANG)
C17: =INDEX(Config!$B$6:$C$104,MATCH("scn.delay_cust.h",Config!$A$6:$A$104,0),LANG)
C19: =INDEX(Config!$B$6:$C$104,MATCH("scn.loss",Config!$A$6:$A$104,0),LANG) | J19: 0
C20: =INDEX(Config!$B$6:$C$104,MATCH("scn.loss.h",Config!$A$6:$A$104,0),LANG)
B21: =INDEX(Config!$B$6:$C$104,MATCH("scn.reset",Config!$A$6:$A$104,0),LANG)
B23: =INDEX(Config!$B$6:$C$104,MATCH("scn.impact",Config!$A$6:$A$104,0),LANG)
B26: =INDEX(Config!$B$6:$C$104,MATCH("scn.low.base",Config!$A$6:$A$104,0),LANG) | F26: =INDEX(Config!$B$6:$C$104,MATCH("scn.low.scn",Config!$A$6:$A$104,0),LANG) | J26: =INDEX(Config!$B$6:$C$104,MATCH("scn.gap",Config!$A$6:$A$104,0),LANG) | N26: =INDEX(Config!$B$6:$C$104,MATCH("scn.firstwarn",Config!$A$6:$A$104,0),LANG)
B27: =MIN(Config!$U$5:$U$16) | F27: =MIN(Config!$V$5:$V$16) | J27: =MIN(Config!$V$5:$V$16)-MIN(Config!$U$5:$U$16) | N27: =IF(MAX(Config!$W$5:$W$16)=0,INDEX(Config!$B$6:$C$104,MATCH("scn.none",Config!$A$6:$A$104,0),LANG),INDEX(Config!$Y$5:$Y$16,MATCH(MAX(Config!$W$5:$W$16),Config!$W$5:$W$16,0)))
B30: =INDEX(Config!$B$6:$C$104,MATCH("sec.table",Config!$A$6:$A$104,0),LANG) | H30: =INDEX(Config!$B$6:$C$104,MATCH("scn.chart",Config!$A$6:$A$104,0),LANG)
B31: =INDEX(Config!$B$6:$C$104,MATCH("th.week",Config!$A$6:$A$104,0),LANG) | C31: =INDEX(Config!$B$6:$C$104,MATCH("th.base",Config!$A$6:$A$104,0),LANG) | D31: =INDEX(Config!$B$6:$C$104,MATCH("th.scn",Config!$A$6:$A$104,0),LANG) | F31: =INDEX(Config!$B$6:$C$104,MATCH("scn.h.diff",Config!$A$6:$A$104,0),LANG)
B32: =Config!$Y$5 | C32: =Config!$U$5 | D32: =Config!$V$5 | F32: =Config!$V$5-Config!$U$5
B33: =Config!$Y$6 | C33: =Config!$U$6 | D33: =Config!$V$6 | F33: =Config!$V$6-Config!$U$6
B34: =Config!$Y$7 | C34: =Config!$U$7 | D34: =Config!$V$7 | F34: =Config!$V$7-Config!$U$7
B35: =Config!$Y$8 | C35: =Config!$U$8 | D35: =Config!$V$8 | F35: =Config!$V$8-Config!$U$8
B36: =Config!$Y$9 | C36: =Config!$U$9 | D36: =Config!$V$9 | F36: =Config!$V$9-Config!$U$9
B37: =Config!$Y$10 | C37: =Config!$U$10 | D37: =Config!$V$10 | F37: =Config!$V$10-Config!$U$10
B38: =Config!$Y$11 | C38: =Config!$U$11 | D38: =Config!$V$11 | F38: =Config!$V$11-Config!$U$11
B39: =Config!$Y$12 | C39: =Config!$U$12 | D39: =Config!$V$12 | F39: =Config!$V$12-Config!$U$12
B40: =Config!$Y$13 | C40: =Config!$U$13 | D40: =Config!$V$13 | F40: =Config!$V$13-Config!$U$13
B41: =Config!$Y$14 | C41: =Config!$U$14 | D41: =Config!$V$14 | F41: =Config!$V$14-Config!$U$14
B42: =Config!$Y$15 | C42: =Config!$U$15 | D42: =Config!$V$15 | F42: =Config!$V$15-Config!$U$15
B43: =Config!$Y$16 | C43: =Config!$U$16 | D43: =Config!$V$16 | F43: =Config!$V$16-Config!$U$16

Sheet Config
A1: CONFIG — Steuerdaten. Bitte nicht verändern. / Control data. Please do not edit.
D2: LANG | E2: =IF(Dashboard!$N$3="English",2,1)
D3: VATON | E3: =IF(COUNTIF($F$8:$G$8,Dashboard!$N$37)>0,1,0) | AB3: =M5 | AC3: =M6 | AD3: =M7 | AE3: =M8 | AF3: =M9 | AG3: =M10 | AH3: =M11 | AI3: =M12 | AJ3: =M13 | AK3: =M14 | AL3: =M15 | AM3: =M16
F4: DE | G4: EN | H4: aktiv/active | J4: Kunden / Customers | L4: Wo | M4: Start | N4: Ende | O4: Ein Basis | P4: Ein Szenario | Q4: Aus fix | R4: Aus variabel | S4: Aus USt | T4: Aus gesamt | U4: =INDEX(Config!$B$6:$C$104,MATCH("ser.base",Config!$A$6:$A$104,0),LANG) | V4: =INDEX(Config!$B$6:$C$104,MATCH("ser.scn",Config!$A$6:$A$104,0),LANG) | W4: Ampel | X4: =INDEX(Config!$B$6:$C$104,MATCH("ser.min",Config!$A$6:$A$104,0),LANG) | Y4: Label | AA4: Tag | AB4: =N5 | AC4: =N6 | AD4: =N7 | AE4: =N8 | AF4: =N9 | AG4: =N10 | AH4: =N11 | AI4: =N12 | AJ4: =N13 | AK4: =N14 | AL4: =N15 | AM4: =N16
A5: Key | B5: Deutsch | C5: English | F5: offen | G5: open | H5: =INDEX(F5:G5,LANG) | J5: =IFERROR(INDEX('Rechnungen | Invoices'!$C$9:$C$108,MATCH(0,INDEX(COUNTIF($J$4:J4,'Rechnungen | Invoices'!$C$9:$C$108)+('Rechnungen | Invoices'!$C$9:$C$108=""),0),0)),"") | L5: 1 | M5: =START | N5: =M5+6 | O5: =SUMIFS('Rechnungen | Invoices'!$Q$9:$Q$108,'Rechnungen | Invoices'!$R$9:$R$108,">="&M5,'Rechnungen | Invoices'!$R$9:$R$108,"<="&N5) | P5: =SUMIFS('Rechnungen | Invoices'!$S$9:$S$108,'Rechnungen | Invoices'!$L$9:$L$108,">="&M5,'Rechnungen | Invoices'!$L$9:$L$108,"<="&N5) | Q5: =AB$25 | R5: =SUMIFS('Kosten | Costs'!$D$34:$D$63,'Kosten | Costs'!$E$34:$E$63,">="&M5,'Kosten | Costs'!$E$34:$E$63,"<="&N5) | S5: =IF(VATON=0,0,IF(AND(DATE(YEAR(M5),MONTH(M5),VATDAY)>=M5,DATE(YEAR(M5),MONTH(M5),VATDAY)<=N5),SUMIFS('Rechnungen | Invoices'!$P$9:$P$108,'Rechnungen | Invoices'!$H$9:$H$108,">="&DATE(YEAR(M5),MONTH(M5)-1,1),'Rechnungen | Invoices'!$H$9:$H$108,"<="&DATE(YEAR(M5),MONTH(M5),1)-1),0)+IF(AND(MONTH(M5)<>MONTH(N5),DATE(YEAR(N5),MONTH(N5),VATDAY)>=M5,DATE(YEAR(N5),MONTH(N5),VATDAY)<=N5),SUMIFS('Rechnungen | Invoices'!$P$9:$P$108,'Rechnungen | Invoices'!$H$9:$H$108,">="&DATE(YEAR(N5),MONTH(N5)-1,1),'Rechnungen | Invoices'!$H$9:$H$108,"<="&DATE(YEAR(N5),MONTH(N5),1)-1),0)) | T5: =Q5+R5+S5 | U5: =OPENBAL+O5-T5 | V5: =OPENBAL+P5-T5 | W5: =IF(V5<MINCASH,2,IF(V5<MINCASH*YELLOWF,1,0)) | X5: =MINCASH | Y5: =INDEX(Config!$B$6:$C$104,MATCH("lbl.week",Config!$A$6:$A$104,0),LANG)&" "&ISOWEEKNUM(M5) | AA5: =IF('Kosten | Costs'!$E$9="",1,MIN(28,MAX(1,'Kosten | Costs'!$E$9))) | AB5: =IF(N('Kosten | Costs'!$D$9)=0,0,IF(OR(AND(DATE(YEAR(AB$3),MONTH(AB$3),$AA5)>=AB$3,DATE(YEAR(AB$3),MONTH(AB$3),$AA5)<=AB$4),AND(DATE(YEAR(AB$4),MONTH(AB$4),$AA5)>=AB$3,DATE(YEAR(AB$4),MONTH(AB$4),$AA5)<=AB$4)),'Kosten | Costs'!$D$9,0)) | AC5: =IF(N('Kosten | Costs'!$D$9)=0,0,IF(OR(AND(DATE(YEAR(AC$3),MONTH(AC$3),$AA5)>=AC$3,DATE(YEAR(AC$3),MONTH(AC$3),$AA5)<=AC$4),AND(DATE(YEAR(AC$4),MONTH(AC$4),$AA5)>=AC$3,DATE(YEAR(AC$4),MONTH(AC$4),$AA5)<=AC$4)),'Kosten | Costs'!$D$9,0)) | AD5: =IF(N('Kosten | Costs'!$D$9)=0,0,IF(OR(AND(DATE(YEAR(AD$3),MONTH(AD$3),$AA5)>=AD$3,DATE(YEAR(AD$3),MONTH(AD$3),$AA5)<=AD$4),AND(DATE(YEAR(AD$4),MONTH(AD$4),$AA5)>=AD$3,DATE(YEAR(AD$4),MONTH(AD$4),$AA5)<=AD$4)),'Kosten | Costs'!$D$9,0)) | AE5: =IF(N('Kosten | Costs'!$D$9)=0,0,IF(OR(AND(DATE(YEAR(AE$3),MONTH(AE$3),$AA5)>=AE$3,DATE(YEAR(AE$3),MONTH(AE$3),$AA5)<=AE$4),AND(DATE(YEAR(AE$4),MONTH(AE$4),$AA5)>=AE$3,DATE(YEAR(AE$4),MONTH(AE$4),$AA5)<=AE$4)),'Kosten | Costs'!$D$9,0)) | AF5: =IF(N('Kosten | Costs'!$D$9)=0,0,IF(OR(AND(DATE(YEAR(AF$3),MONTH(AF$3),$AA5)>=AF$3,DATE(YEAR(AF$3),MONTH(AF$3),$AA5)<=AF$4),AND(DATE(YEAR(AF$4),MONTH(AF$4),$AA5)>=AF$3,DATE(YEAR(AF$4),MONTH(AF$4),$AA5)<=AF$4)),'Kosten | Costs'!$D$9,0)) | AG5: =IF(N('Kosten | Costs'!$D$9)=0,0,IF(OR(AND(DATE(YEAR(AG$3),MONTH(AG$3),$AA5)>=AG$3,DATE(YEAR(AG$3),MONTH(AG$3),$AA5)<=AG$4),AND(DATE(YEAR(AG$4),MONTH(AG$4),$AA5)>=AG$3,DATE(YEAR(AG$4),MONTH(AG$4),$AA5)<=AG$4)),'Kosten | Costs'!$D$9,0)) | AH5: =IF(N('Kosten | Costs'!$D$9)=0,0,IF(OR(AND(DATE(YEAR(AH$3),MONTH(AH$3),$AA5)>=AH$3,DATE(YEAR(AH$3),MONTH(AH$3),$AA5)<=AH$4),AND(DATE(YEAR(AH$4),MONTH(AH$4),$AA5)>=AH$3,DATE(YEAR(AH$4),MONTH(AH$4),$AA5)<=AH$4)),'Kosten | Costs'!$D$9,0)) | AI5: =IF(N('Kosten | Costs'!$D$9)=0,0,IF(OR(AND(DATE(YEAR(AI$3),MONTH(AI$3),$AA5)>=AI$3,DATE(YEAR(AI$3),MONTH(AI$3),$AA5)<=AI$4),AND(DATE(YEAR(AI$4),MONTH(AI$4),$AA5)>=AI$3,DATE(YEAR(AI$4),MONTH(AI$4),$AA5)<=AI$4)),'Kosten | Costs'!$D$9,0)) | ... AM5: =IF(N('Kosten | Costs'!$D$9)=0,0,IF(OR(AND(DATE(YEAR(AM$3),MONTH(AM$3),$AA5)>=AM$3,DATE(YEAR(AM$3),MONTH(AM$3),$AA5)<=AM$4),AND(DATE(YEAR(AM$4),MONTH(AM$4),$AA5)>=AM$3,DATE(YEAR(AM$4),MONTH(AM$4),$AA5)<=AM$4)),'Kosten | Costs'!$D$9,0))
A6: app.title | B6: Cashflow-Frühwarnsystem | C6: Cashflow Early Warning System | F6: bezahlt | G6: paid | H6: =INDEX(F6:G6,LANG) | J6: =IFERROR(INDEX('Rechnungen | Invoices'!$C$9:$C$108,MATCH(0,INDEX(COUNTIF($J$4:J5,'Rechnungen | Invoices'!$C$9:$C$108)+('Rechnungen | Invoices'!$C$9:$C$108=""),0),0)),"") | L6: 2 | M6: =M5+7 | N6: =M6+6 | O6: =SUMIFS('Rechnungen | Invoices'!$Q$9:$Q$108,'Rechnungen | Invoices'!$R$9:$R$108,">="&M6,'Rechnungen | Invoices'!$R$9:$R$108,"<="&N6) | P6: =SUMIFS('Rechnungen | Invoices'!$S$9:$S$108,'Rechnungen | Invoices'!$L$9:$L$108,">="&M6,'Rechnungen | Invoices'!$L$9:$L$108,"<="&N6) | Q6: =AC$25 | R6: =SUMIFS('Kosten | Costs'!$D$34:$D$63,'Kosten | Costs'!$E$34:$E$63,">="&M6,'Kosten | Costs'!$E$34:$E$63,"<="&N6) | S6: =IF(VATON=0,0,IF(AND(DATE(YEAR(M6),MONTH(M6),VATDAY)>=M6,DATE(YEAR(M6),MONTH(M6),VATDAY)<=N6),SUMIFS('Rechnungen | Invoices'!$P$9:$P$108,'Rechnungen | Invoices'!$H$9:$H$108,">="&DATE(YEAR(M6),MONTH(M6)-1,1),'Rechnungen | Invoices'!$H$9:$H$108,"<="&DATE(YEAR(M6),MONTH(M6),1)-1),0)+IF(AND(MONTH(M6)<>MONTH(N6),DATE(YEAR(N6),MONTH(N6),VATDAY)>=M6,DATE(YEAR(N6),MONTH(N6),VATDAY)<=N6),SUMIFS('Rechnungen | Invoices'!$P$9:$P$108,'Rechnungen | Invoices'!$H$9:$H$108,">="&DATE(YEAR(N6),MONTH(N6)-1,1),'Rechnungen | Invoices'!$H$9:$H$108,"<="&DATE(YEAR(N6),MONTH(N6),1)-1),0)) | T6: =Q6+R6+S6 | U6: =U5+O6-T6 | V6: =V5+P6-T6 | W6: =IF(V6<MINCASH,2,IF(V6<MINCASH*YELLOWF,1,0)) | X6: =MINCASH | Y6: =INDEX(Config!$B$6:$C$104,MATCH("lbl.week",Config!$A$6:$A$104,0),LANG)&" "&ISOWEEKNUM(M6) | AA6: =IF('Kosten | Costs'!$E$10="",1,MIN(28,MAX(1,'Kosten | Costs'!$E$10))) | AB6: =IF(N('Kosten | Costs'!$D$10)=0,0,IF(OR(AND(DATE(YEAR(AB$3),MONTH(AB$3),$AA6)>=AB$3,DATE(YEAR(AB$3),MONTH(AB$3),$AA6)<=AB$4),AND(DATE(YEAR(AB$4),MONTH(AB$4),$AA6)>=AB$3,DATE(YEAR(AB$4),MONTH(AB$4),$AA6)<=AB$4)),'Kosten | Costs'!$D$10,0)) | AC6: =IF(N('Kosten | Costs'!$D$10)=0,0,IF(OR(AND(DATE(YEAR(AC$3),MONTH(AC$3),$AA6)>=AC$3,DATE(YEAR(AC$3),MONTH(AC$3),$AA6)<=AC$4),AND(DATE(YEAR(AC$4),MONTH(AC$4),$AA6)>=AC$3,DATE(YEAR(AC$4),MONTH(AC$4),$AA6)<=AC$4)),'Kosten | Costs'!$D$10,0)) | AD6: =IF(N('Kosten | Costs'!$D$10)=0,0,IF(OR(AND(DATE(YEAR(AD$3),MONTH(AD$3),$AA6)>=AD$3,DATE(YEAR(AD$3),MONTH(AD$3),$AA6)<=AD$4),AND(DATE(YEAR(AD$4),MONTH(AD$4),$AA6)>=AD$3,DATE(YEAR(AD$4),MONTH(AD$4),$AA6)<=AD$4)),'Kosten | Costs'!$D$10,0)) | AE6: =IF(N('Kosten | Costs'!$D$10)=0,0,IF(OR(AND(DATE(YEAR(AE$3),MONTH(AE$3),$AA6)>=AE$3,DATE(YEAR(AE$3),MONTH(AE$3),$AA6)<=AE$4),AND(DATE(YEAR(AE$4),MONTH(AE$4),$AA6)>=AE$3,DATE(YEAR(AE$4),MONTH(AE$4),$AA6)<=AE$4)),'Kosten | Costs'!$D$10,0)) | AF6: =IF(N('Kosten | Costs'!$D$10)=0,0,IF(OR(AND(DATE(YEAR(AF$3),MONTH(AF$3),$AA6)>=AF$3,DATE(YEAR(AF$3),MONTH(AF$3),$AA6)<=AF$4),AND(DATE(YEAR(AF$4),MONTH(AF$4),$AA6)>=AF$3,DATE(YEAR(AF$4),MONTH(AF$4),$AA6)<=AF$4)),'Kosten | Costs'!$D$10,0)) | AG6: =IF(N('Kosten | Costs'!$D$10)=0,0,IF(OR(AND(DATE(YEAR(AG$3),MONTH(AG$3),$AA6)>=AG$3,DATE(YEAR(AG$3),MONTH(AG$3),$AA6)<=AG$4),AND(DATE(YEAR(AG$4),MONTH(AG$4),$AA6)>=AG$3,DATE(YEAR(AG$4),MONTH(AG$4),$AA6)<=AG$4)),'Kosten | Costs'!$D$10,0)) | AH6: =IF(N('Kosten | Costs'!$D$10)=0,0,IF(OR(AND(DATE(YEAR(AH$3),MONTH(AH$3),$AA6)>=AH$3,DATE(YEAR(AH$3),MONTH(AH$3),$AA6)<=AH$4),AND(DATE(YEAR(AH$4),MONTH(AH$4),$AA6)>=AH$3,DATE(YEAR(AH$4),MONTH(AH$4),$AA6)<=AH$4)),'Kosten | Costs'!$D$10,0)) | AI6: =IF(N('Kosten | Costs'!$D$10)=0,0,IF(OR(AND(DATE(YEAR(AI$3),MONTH(AI$3),$AA6)>=AI$3,DATE(YEAR(AI$3),MONTH(AI$3),$AA6)<=AI$4),AND(DATE(YEAR(AI$4),MONTH(AI$4),$AA6)>=AI$3,DATE(YEAR(AI$4),MONTH(AI$4),$AA6)<=AI$4)),'Kosten | Costs'!$D$10,0)) | ... AM6: =IF(N('Kosten | Costs'!$D$10)=0,0,IF(OR(AND(DATE(YEAR(AM$3),MONTH(AM$3),$AA6)>=AM$3,DATE(YEAR(AM$3),MONTH(AM$3),$AA6)<=AM$4),AND(DATE(YEAR(AM$4),MONTH(AM$4),$AA6)>=AM$3,DATE(YEAR(AM$4),MONTH(AM$4),$AA6)<=AM$4)),'Kosten | Costs'!$D$10,0))
A7: app.sub | B7: Liquiditätsplanung für Kleinunternehmer und Selbstständige | C7: Liquidity planning for small businesses and freelancers | J7: =IFERROR(INDEX('Rechnungen | Invoices'!$C$9:$C$108,MATCH(0,INDEX(COUNTIF($J$4:J6,'Rechnungen | Invoices'!$C$9:$C$108)+('Rechnungen | Invoices'!$C$9:$C$108=""),0),0)),"") | L7: 3 | M7: =M6+7 | N7: =M7+6 | O7: =SUMIFS('Rechnungen | Invoices'!$Q$9:$Q$108,'Rechnungen | Invoices'!$R$9:$R$108,">="&M7,'Rechnungen | Invoices'!$R$9:$R$108,"<="&N7) | P7: =SUMIFS('Rechnungen | Invoices'!$S$9:$S$108,'Rechnungen | Invoices'!$L$9:$L$108,">="&M7,'Rechnungen | Invoices'!$L$9:$L$108,"<="&N7) | Q7: =AD$25 | R7: =SUMIFS('Kosten | Costs'!$D$34:$D$63,'Kosten | Costs'!$E$34:$E$63,">="&M7,'Kosten | Costs'!$E$34:$E$63,"<="&N7) | S7: =IF(VATON=0,0,IF(AND(DATE(YEAR(M7),MONTH(M7),VATDAY)>=M7,DATE(YEAR(M7),MONTH(M7),VATDAY)<=N7),SUMIFS('Rechnungen | Invoices'!$P$9:$P$108,'Rechnungen | Invoices'!$H$9:$H$108,">="&DATE(YEAR(M7),MONTH(M7)-1,1),'Rechnungen | Invoices'!$H$9:$H$108,"<="&DATE(YEAR(M7),MONTH(M7),1)-1),0)+IF(AND(MONTH(M7)<>MONTH(N7),DATE(YEAR(N7),MONTH(N7),VATDAY)>=M7,DATE(YEAR(N7),MONTH(N7),VATDAY)<=N7),SUMIFS('Rechnungen | Invoices'!$P$9:$P$108,'Rechnungen | Invoices'!$H$9:$H$108,">="&DATE(YEAR(N7),MONTH(N7)-1,1),'Rechnungen | Invoices'!$H$9:$H$108,"<="&DATE(YEAR(N7),MONTH(N7),1)-1),0)) | T7: =Q7+R7+S7 | U7: =U6+O7-T7 | V7: =V6+P7-T7 | W7: =IF(V7<MINCASH,2,IF(V7<MINCASH*YELLOWF,1,0)) | X7: =MINCASH | Y7: =INDEX(Config!$B$6:$C$104,MATCH("lbl.week",Config!$A$6:$A$104,0),LANG)&" "&ISOWEEKNUM(M7) | AA7: =IF('Kosten | Costs'!$E$11="",1,MIN(28,MAX(1,'Kosten | Costs'!$E$11))) | AB7: =IF(N('Kosten | Costs'!$D$11)=0,0,IF(OR(AND(DATE(YEAR(AB$3),MONTH(AB$3),$AA7)>=AB$3,DATE(YEAR(AB$3),MONTH(AB$3),$AA7)<=AB$4),AND(DATE(YEAR(AB$4),MONTH(AB$4),$AA7)>=AB$3,DATE(YEAR(AB$4),MONTH(AB$4),$AA7)<=AB$4)),'Kosten | Costs'!$D$11,0)) | AC7: =IF(N('Kosten | Costs'!$D$11)=0,0,IF(OR(AND(DATE(YEAR(AC$3),MONTH(AC$3),$AA7)>=AC$3,DATE(YEAR(AC$3),MONTH(AC$3),$AA7)<=AC$4),AND(DATE(YEAR(AC$4),MONTH(AC$4),$AA7)>=AC$3,DATE(YEAR(AC$4),MONTH(AC$4),$AA7)<=AC$4)),'Kosten | Costs'!$D$11,0)) | AD7: =IF(N('Kosten | Costs'!$D$11)=0,0,IF(OR(AND(DATE(YEAR(AD$3),MONTH(AD$3),$AA7)>=AD$3,DATE(YEAR(AD$3),MONTH(AD$3),$AA7)<=AD$4),AND(DATE(YEAR(AD$4),MONTH(AD$4),$AA7)>=AD$3,DATE(YEAR(AD$4),MONTH(AD$4),$AA7)<=AD$4)),'Kosten | Costs'!$D$11,0)) | AE7: =IF(N('Kosten | Costs'!$D$11)=0,0,IF(OR(AND(DATE(YEAR(AE$3),MONTH(AE$3),$AA7)>=AE$3,DATE(YEAR(AE$3),MONTH(AE$3),$AA7)<=AE$4),AND(DATE(YEAR(AE$4),MONTH(AE$4),$AA7)>=AE$3,DATE(YEAR(AE$4),MONTH(AE$4),$AA7)<=AE$4)),'Kosten | Costs'!$D$11,0)) | AF7: =IF(N('Kosten | Costs'!$D$11)=0,0,IF(OR(AND(DATE(YEAR(AF$3),MONTH(AF$3),$AA7)>=AF$3,DATE(YEAR(AF$3),MONTH(AF$3),$AA7)<=AF$4),AND(DATE(YEAR(AF$4),MONTH(AF$4),$AA7)>=AF$3,DATE(YEAR(AF$4),MONTH(AF$4),$AA7)<=AF$4)),'Kosten | Costs'!$D$11,0)) | AG7: =IF(N('Kosten | Costs'!$D$11)=0,0,IF(OR(AND(DATE(YEAR(AG$3),MONTH(AG$3),$AA7)>=AG$3,DATE(YEAR(AG$3),MONTH(AG$3),$AA7)<=AG$4),AND(DATE(YEAR(AG$4),MONTH(AG$4),$AA7)>=AG$3,DATE(YEAR(AG$4),MONTH(AG$4),$AA7)<=AG$4)),'Kosten | Costs'!$D$11,0)) | AH7: =IF(N('Kosten | Costs'!$D$11)=0,0,IF(OR(AND(DATE(YEAR(AH$3),MONTH(AH$3),$AA7)>=AH$3,DATE(YEAR(AH$3),MONTH(AH$3),$AA7)<=AH$4),AND(DATE(YEAR(AH$4),MONTH(AH$4),$AA7)>=AH$3,DATE(YEAR(AH$4),MONTH(AH$4),$AA7)<=AH$4)),'Kosten | Costs'!$D$11,0)) | AI7: =IF(N('Kosten | Costs'!$D$11)=0,0,IF(OR(AND(DATE(YEAR(AI$3),MONTH(AI$3),$AA7)>=AI$3,DATE(YEAR(AI$3),MONTH(AI$3),$AA7)<=AI$4),AND(DATE(YEAR(AI$4),MONTH(AI$4),$AA7)>=AI$3,DATE(YEAR(AI$4),MONTH(AI$4),$AA7)<=AI$4)),'Kosten | Costs'!$D$11,0)) | ... AM7: =IF(N('Kosten | Costs'!$D$11)=0,0,IF(OR(AND(DATE(YEAR(AM$3),MONTH(AM$3),$AA7)>=AM$3,DATE(YEAR(AM$3),MONTH(AM$3),$AA7)<=AM$4),AND(DATE(YEAR(AM$4),MONTH(AM$4),$AA7)>=AM$3,DATE(YEAR(AM$4),MONTH(AM$4),$AA7)<=AM$4)),'Kosten | Costs'!$D$11,0))
A8: ui.language | B8: Sprache / Language | C8: Sprache / Language | F8: Ja | G8: Yes | H8: =INDEX(F8:G8,LANG) | J8: =IFERROR(INDEX('Rechnungen | Invoices'!$C$9:$C$108,MATCH(0,INDEX(COUNTIF($J$4:J7,'Rechnungen | Invoices'!$C$9:$C$108)+('Rechnungen | Invoices'!$C$9:$C$108=""),0),0)),"") | L8: 4 | M8: =M7+7 | N8: =M8+6 | O8: =SUMIFS('Rechnungen | Invoices'!$Q$9:$Q$108,'Rechnungen | Invoices'!$R$9:$R$108,">="&M8,'Rechnungen | Invoices'!$R$9:$R$108,"<="&N8) | P8: =SUMIFS('Rechnungen | Invoices'!$S$9:$S$108,'Rechnungen | Invoices'!$L$9:$L$108,">="&M8,'Rechnungen | Invoices'!$L$9:$L$108,"<="&N8) | Q8: =AE$25 | R8: =SUMIFS('Kosten | Costs'!$D$34:$D$63,'Kosten | Costs'!$E$34:$E$63,">="&M8,'Kosten | Costs'!$E$34:$E$63,"<="&N8) | S8: =IF(VATON=0,0,IF(AND(DATE(YEAR(M8),MONTH(M8),VATDAY)>=M8,DATE(YEAR(M8),MONTH(M8),VATDAY)<=N8),SUMIFS('Rechnungen | Invoices'!$P$9:$P$108,'Rechnungen | Invoices'!$H$9:$H$108,">="&DATE(YEAR(M8),MONTH(M8)-1,1),'Rechnungen | Invoices'!$H$9:$H$108,"<="&DATE(YEAR(M8),MONTH(M8),1)-1),0)+IF(AND(MONTH(M8)<>MONTH(N8),DATE(YEAR(N8),MONTH(N8),VATDAY)>=M8,DATE(YEAR(N8),MONTH(N8),VATDAY)<=N8),SUMIFS('Rechnungen | Invoices'!$P$9:$P$108,'Rechnungen | Invoices'!$H$9:$H$108,">="&DATE(YEAR(N8),MONTH(N8)-1,1),'Rechnungen | Invoices'!$H$9:$H$108,"<="&DATE(YEAR(N8),MONTH(N8),1)-1),0)) | T8: =Q8+R8+S8 | U8: =U7+O8-T8 | V8: =V7+P8-T8 | W8: =IF(V8<MINCASH,2,IF(V8<MINCASH*YELLOWF,1,0)) | X8: =MINCASH | Y8: =INDEX(Config!$B$6:$C$104,MATCH("lbl.week",Config!$A$6:$A$104,0),LANG)&" "&ISOWEEKNUM(M8) | AA8: =IF('Kosten | Costs'!$E$12="",1,MIN(28,MAX(1,'Kosten | Costs'!$E$12))) | AB8: =IF(N('Kosten | Costs'!$D$12)=0,0,IF(OR(AND(DATE(YEAR(AB$3),MONTH(AB$3),$AA8)>=AB$3,DATE(YEAR(AB$3),MONTH(AB$3),$AA8)<=AB$4),AND(DATE(YEAR(AB$4),MONTH(AB$4),$AA8)>=AB$3,DATE(YEAR(AB$4),MONTH(AB$4),$AA8)<=AB$4)),'Kosten | Costs'!$D$12,0)) | AC8: =IF(N('Kosten | Costs'!$D$12)=0,0,IF(OR(AND(DATE(YEAR(AC$3),MONTH(AC$3),$AA8)>=AC$3,DATE(YEAR(AC$3),MONTH(AC$3),$AA8)<=AC$4),AND(DATE(YEAR(AC$4),MONTH(AC$4),$AA8)>=AC$3,DATE(YEAR(AC$4),MONTH(AC$4),$AA8)<=AC$4)),'Kosten | Costs'!$D$12,0)) | AD8: =IF(N('Kosten | Costs'!$D$12)=0,0,IF(OR(AND(DATE(YEAR(AD$3),MONTH(AD$3),$AA8)>=AD$3,DATE(YEAR(AD$3),MONTH(AD$3),$AA8)<=AD$4),AND(DATE(YEAR(AD$4),MONTH(AD$4),$AA8)>=AD$3,DATE(YEAR(AD$4),MONTH(AD$4),$AA8)<=AD$4)),'Kosten | Costs'!$D$12,0)) | AE8: =IF(N('Kosten | Costs'!$D$12)=0,0,IF(OR(AND(DATE(YEAR(AE$3),MONTH(AE$3),$AA8)>=AE$3,DATE(YEAR(AE$3),MONTH(AE$3),$AA8)<=AE$4),AND(DATE(YEAR(AE$4),MONTH(AE$4),$AA8)>=AE$3,DATE(YEAR(AE$4),MONTH(AE$4),$AA8)<=AE$4)),'Kosten | Costs'!$D$12,0)) | AF8: =IF(N('Kosten | Costs'!$D$12)=0,0,IF(OR(AND(DATE(YEAR(AF$3),MONTH(AF$3),$AA8)>=AF$3,DATE(YEAR(AF$3),MONTH(AF$3),$AA8)<=AF$4),AND(DATE(YEAR(AF$4),MONTH(AF$4),$AA8)>=AF$3,DATE(YEAR(AF$4),MONTH(AF$4),$AA8)<=AF$4)),'Kosten | Costs'!$D$12,0)) | AG8: =IF(N('Kosten | Costs'!$D$12)=0,0,IF(OR(AND(DATE(YEAR(AG$3),MONTH(AG$3),$AA8)>=AG$3,DATE(YEAR(AG$3),MONTH(AG$3),$AA8)<=AG$4),AND(DATE(YEAR(AG$4),MONTH(AG$4),$AA8)>=AG$3,DATE(YEAR(AG$4),MONTH(AG$4),$AA8)<=AG$4)),'Kosten | Costs'!$D$12,0)) | AH8: =IF(N('Kosten | Costs'!$D$12)=0,0,IF(OR(AND(DATE(YEAR(AH$3),MONTH(AH$3),$AA8)>=AH$3,DATE(YEAR(AH$3),MONTH(AH$3),$AA8)<=AH$4),AND(DATE(YEAR(AH$4),MONTH(AH$4),$AA8)>=AH$3,DATE(YEAR(AH$4),MONTH(AH$4),$AA8)<=AH$4)),'Kosten | Costs'!$D$12,0)) | AI8: =IF(N('Kosten | Costs'!$D$12)=0,0,IF(OR(AND(DATE(YEAR(AI$3),MONTH(AI$3),$AA8)>=AI$3,DATE(YEAR(AI$3),MONTH(AI$3),$AA8)<=AI$4),AND(DATE(YEAR(AI$4),MONTH(AI$4),$AA8)>=AI$3,DATE(YEAR(AI$4),MONTH(AI$4),$AA8)<=AI$4)),'Kosten | Costs'!$D$12,0)) | ... AM8: =IF(N('Kosten | Costs'!$D$12)=0,0,IF(OR(AND(DATE(YEAR(AM$3),MONTH(AM$3),$AA8)>=AM$3,DATE(YEAR(AM$3),MONTH(AM$3),$AA8)<=AM$4),AND(DATE(YEAR(AM$4),MONTH(AM$4),$AA8)>=AM$3,DATE(YEAR(AM$4),MONTH(AM$4),$AA8)<=AM$4)),'Kosten | Costs'!$D$12,0))
A9: kpi.balance | B9: Kontostand heute | C9: Cash balance today | F9: Nein | G9: No | H9: =INDEX(F9:G9,LANG) | J9: =IFERROR(INDEX('Rechnungen | Invoices'!$C$9:$C$108,MATCH(0,INDEX(COUNTIF($J$4:J8,'Rechnungen | Invoices'!$C$9:$C$108)+('Rechnungen | Invoices'!$C$9:$C$108=""),0),0)),"") | L9: 5 | M9: =M8+7 | N9: =M9+6 | O9: =SUMIFS('Rechnungen | Invoices'!$Q$9:$Q$108,'Rechnungen | Invoices'!$R$9:$R$108,">="&M9,'Rechnungen | Invoices'!$R$9:$R$108,"<="&N9) | P9: =SUMIFS('Rechnungen | Invoices'!$S$9:$S$108,'Rechnungen | Invoices'!$L$9:$L$108,">="&M9,'Rechnungen | Invoices'!$L$9:$L$108,"<="&N9) | Q9: =AF$25 | R9: =SUMIFS('Kosten | Costs'!$D$34:$D$63,'Kosten | Costs'!$E$34:$E$63,">="&M9,'Kosten | Costs'!$E$34:$E$63,"<="&N9) | S9: =IF(VATON=0,0,IF(AND(DATE(YEAR(M9),MONTH(M9),VATDAY)>=M9,DATE(YEAR(M9),MONTH(M9),VATDAY)<=N9),SUMIFS('Rechnungen | Invoices'!$P$9:$P$108,'Rechnungen | Invoices'!$H$9:$H$108,">="&DATE(YEAR(M9),MONTH(M9)-1,1),'Rechnungen | Invoices'!$H$9:$H$108,"<="&DATE(YEAR(M9),MONTH(M9),1)-1),0)+IF(AND(MONTH(M9)<>MONTH(N9),DATE(YEAR(N9),MONTH(N9),VATDAY)>=M9,DATE(YEAR(N9),MONTH(N9),VATDAY)<=N9),SUMIFS('Rechnungen | Invoices'!$P$9:$P$108,'Rechnungen | Invoices'!$H$9:$H$108,">="&DATE(YEAR(N9),MONTH(N9)-1,1),'Rechnungen | Invoices'!$H$9:$H$108,"<="&DATE(YEAR(N9),MONTH(N9),1)-1),0)) | T9: =Q9+R9+S9 | U9: =U8+O9-T9 | V9: =V8+P9-T9 | W9: =IF(V9<MINCASH,2,IF(V9<MINCASH*YELLOWF,1,0)) | X9: =MINCASH | Y9: =INDEX(Config!$B$6:$C$104,MATCH("lbl.week",Config!$A$6:$A$104,0),LANG)&" "&ISOWEEKNUM(M9) | AA9: =IF('Kosten | Costs'!$E$13="",1,MIN(28,MAX(1,'Kosten | Costs'!$E$13))) | AB9: =IF(N('Kosten | Costs'!$D$13)=0,0,IF(OR(AND(DATE(YEAR(AB$3),MONTH(AB$3),$AA9)>=AB$3,DATE(YEAR(AB$3),MONTH(AB$3),$AA9)<=AB$4),AND(DATE(YEAR(AB$4),MONTH(AB$4),$AA9)>=AB$3,DATE(YEAR(AB$4),MONTH(AB$4),$AA9)<=AB$4)),'Kosten | Costs'!$D$13,0)) | AC9: =IF(N('Kosten | Costs'!$D$13)=0,0,IF(OR(AND(DATE(YEAR(AC$3),MONTH(AC$3),$AA9)>=AC$3,DATE(YEAR(AC$3),MONTH(AC$3),$AA9)<=AC$4),AND(DATE(YEAR(AC$4),MONTH(AC$4),$AA9)>=AC$3,DATE(YEAR(AC$4),MONTH(AC$4),$AA9)<=AC$4)),'Kosten | Costs'!$D$13,0)) | AD9: =IF(N('Kosten | Costs'!$D$13)=0,0,IF(OR(AND(DATE(YEAR(AD$3),MONTH(AD$3),$AA9)>=AD$3,DATE(YEAR(AD$3),MONTH(AD$3),$AA9)<=AD$4),AND(DATE(YEAR(AD$4),MONTH(AD$4),$AA9)>=AD$3,DATE(YEAR(AD$4),MONTH(AD$4),$AA9)<=AD$4)),'Kosten | Costs'!$D$13,0)) | AE9: =IF(N('Kosten | Costs'!$D$13)=0,0,IF(OR(AND(DATE(YEAR(AE$3),MONTH(AE$3),$AA9)>=AE$3,DATE(YEAR(AE$3),MONTH(AE$3),$AA9)<=AE$4),AND(DATE(YEAR(AE$4),MONTH(AE$4),$AA9)>=AE$3,DATE(YEAR(AE$4),MONTH(AE$4),$AA9)<=AE$4)),'Kosten | Costs'!$D$13,0)) | AF9: =IF(N('Kosten | Costs'!$D$13)=0,0,IF(OR(AND(DATE(YEAR(AF$3),MONTH(AF$3),$AA9)>=AF$3,DATE(YEAR(AF$3),MONTH(AF$3),$AA9)<=AF$4),AND(DATE(YEAR(AF$4),MONTH(AF$4),$AA9)>=AF$3,DATE(YEAR(AF$4),MONTH(AF$4),$AA9)<=AF$4)),'Kosten | Costs'!$D$13,0)) | AG9: =IF(N('Kosten | Costs'!$D$13)=0,0,IF(OR(AND(DATE(YEAR(AG$3),MONTH(AG$3),$AA9)>=AG$3,DATE(YEAR(AG$3),MONTH(AG$3),$AA9)<=AG$4),AND(DATE(YEAR(AG$4),MONTH(AG$4),$AA9)>=AG$3,DATE(YEAR(AG$4),MONTH(AG$4),$AA9)<=AG$4)),'Kosten | Costs'!$D$13,0)) | AH9: =IF(N('Kosten | Costs'!$D$13)=0,0,IF(OR(AND(DATE(YEAR(AH$3),MONTH(AH$3),$AA9)>=AH$3,DATE(YEAR(AH$3),MONTH(AH$3),$AA9)<=AH$4),AND(DATE(YEAR(AH$4),MONTH(AH$4),$AA9)>=AH$3,DATE(YEAR(AH$4),MONTH(AH$4),$AA9)<=AH$4)),'Kosten | Costs'!$D$13,0)) | AI9: =IF(N('Kosten | Costs'!$D$13)=0,0,IF(OR(AND(DATE(YEAR(AI$3),MONTH(AI$3),$AA9)>=AI$3,DATE(YEAR(AI$3),MONTH(AI$3),$AA9)<=AI$4),AND(DATE(YEAR(AI$4),MONTH(AI$4),$AA9)>=AI$3,DATE(YEAR(AI$4),MONTH(AI$4),$AA9)<=AI$4)),'Kosten | Costs'!$D$13,0)) | ... AM9: =IF(N('Kosten | Costs'!$D$13)=0,0,IF(OR(AND(DATE(YEAR(AM$3),MONTH(AM$3),$AA9)>=AM$3,DATE(YEAR(AM$3),MONTH(AM$3),$AA9)<=AM$4),AND(DATE(YEAR(AM$4),MONTH(AM$4),$AA9)>=AM$3,DATE(YEAR(AM$4),MONTH(AM$4),$AA9)<=AM$4)),'Kosten | Costs'!$D$13,0))
A10: kpi.balance.sub | B10: Startwert der Prognose | C10: starting value of the forecast | J10: =IFERROR(INDEX('Rechnungen | Invoices'!$C$9:$C$108,MATCH(0,INDEX(COUNTIF($J$4:J9,'Rechnungen | Invoices'!$C$9:$C$108)+('Rechnungen | Invoices'!$C$9:$C$108=""),0),0)),"") | L10: 6 | M10: =M9+7 | N10: =M10+6 | O10: =SUMIFS('Rechnungen | Invoices'!$Q$9:$Q$108,'Rechnungen | Invoices'!$R$9:$R$108,">="&M10,'Rechnungen | Invoices'!$R$9:$R$108,"<="&N10) | P10: =SUMIFS('Rechnungen | Invoices'!$S$9:$S$108,'Rechnungen | Invoices'!$L$9:$L$108,">="&M10,'Rechnungen | Invoices'!$L$9:$L$108,"<="&N10) | Q10: =AG$25 | R10: =SUMIFS('Kosten | Costs'!$D$34:$D$63,'Kosten | Costs'!$E$34:$E$63,">="&M10,'Kosten | Costs'!$E$34:$E$63,"<="&N10) | S10: =IF(VATON=0,0,IF(AND(DATE(YEAR(M10),MONTH(M10),VATDAY)>=M10,DATE(YEAR(M10),MONTH(M10),VATDAY)<=N10),SUMIFS('Rechnungen | Invoices'!$P$9:$P$108,'Rechnungen | Invoices'!$H$9:$H$108,">="&DATE(YEAR(M10),MONTH(M10)-1,1),'Rechnungen | Invoices'!$H$9:$H$108,"<="&DATE(YEAR(M10),MONTH(M10),1)-1),0)+IF(AND(MONTH(M10)<>MONTH(N10),DATE(YEAR(N10),MONTH(N10),VATDAY)>=M10,DATE(YEAR(N10),MONTH(N10),VATDAY)<=N10),SUMIFS('Rechnungen | Invoices'!$P$9:$P$108,'Rechnungen | Invoices'!$H$9:$H$108,">="&DATE(YEAR(N10),MONTH(N10)-1,1),'Rechnungen | Invoices'!$H$9:$H$108,"<="&DATE(YEAR(N10),MONTH(N10),1)-1),0)) | T10: =Q10+R10+S10 | U10: =U9+O10-T10 | V10: =V9+P10-T10 | W10: =IF(V10<MINCASH,2,IF(V10<MINCASH*YELLOWF,1,0)) | X10: =MINCASH | Y10: =INDEX(Config!$B$6:$C$104,MATCH("lbl.week",Config!$A$6:$A$104,0),LANG)&" "&ISOWEEKNUM(M10) | AA10: =IF('Kosten | Costs'!$E$14="",1,MIN(28,MAX(1,'Kosten | Costs'!$E$14))) | AB10: =IF(N('Kosten | Costs'!$D$14)=0,0,IF(OR(AND(DATE(YEAR(AB$3),MONTH(AB$3),$AA10)>=AB$3,DATE(YEAR(AB$3),MONTH(AB$3),$AA10)<=AB$4),AND(DATE(YEAR(AB$4),MONTH(AB$4),$AA10)>=AB$3,DATE(YEAR(AB$4),MONTH(AB$4),$AA10)<=AB$4)),'Kosten | Costs'!$D$14,0)) | AC10: =IF(N('Kosten | Costs'!$D$14)=0,0,IF(OR(AND(DATE(YEAR(AC$3),MONTH(AC$3),$AA10)>=AC$3,DATE(YEAR(AC$3),MONTH(AC$3),$AA10)<=AC$4),AND(DATE(YEAR(AC$4),MONTH(AC$4),$AA10)>=AC$3,DATE(YEAR(AC$4),MONTH(AC$4),$AA10)<=AC$4)),'Kosten | Costs'!$D$14,0)) | AD10: =IF(N('Kosten | Costs'!$D$14)=0,0,IF(OR(AND(DATE(YEAR(AD$3),MONTH(AD$3),$AA10)>=AD$3,DATE(YEAR(AD$3),MONTH(AD$3),$AA10)<=AD$4),AND(DATE(YEAR(AD$4),MONTH(AD$4),$AA10)>=AD$3,DATE(YEAR(AD$4),MONTH(AD$4),$AA10)<=AD$4)),'Kosten | Costs'!$D$14,0)) | AE10: =IF(N('Kosten | Costs'!$D$14)=0,0,IF(OR(AND(DATE(YEAR(AE$3),MONTH(AE$3),$AA10)>=AE$3,DATE(YEAR(AE$3),MONTH(AE$3),$AA10)<=AE$4),AND(DATE(YEAR(AE$4),MONTH(AE$4),$AA10)>=AE$3,DATE(YEAR(AE$4),MONTH(AE$4),$AA10)<=AE$4)),'Kosten | Costs'!$D$14,0)) | AF10: =IF(N('Kosten | Costs'!$D$14)=0,0,IF(OR(AND(DATE(YEAR(AF$3),MONTH(AF$3),$AA10)>=AF$3,DATE(YEAR(AF$3),MONTH(AF$3),$AA10)<=AF$4),AND(DATE(YEAR(AF$4),MONTH(AF$4),$AA10)>=AF$3,DATE(YEAR(AF$4),MONTH(AF$4),$AA10)<=AF$4)),'Kosten | Costs'!$D$14,0)) | AG10: =IF(N('Kosten | Costs'!$D$14)=0,0,IF(OR(AND(DATE(YEAR(AG$3),MONTH(AG$3),$AA10)>=AG$3,DATE(YEAR(AG$3),MONTH(AG$3),$AA10)<=AG$4),AND(DATE(YEAR(AG$4),MONTH(AG$4),$AA10)>=AG$3,DATE(YEAR(AG$4),MONTH(AG$4),$AA10)<=AG$4)),'Kosten | Costs'!$D$14,0)) | AH10: =IF(N('Kosten | Costs'!$D$14)=0,0,IF(OR(AND(DATE(YEAR(AH$3),MONTH(AH$3),$AA10)>=AH$3,DATE(YEAR(AH$3),MONTH(AH$3),$AA10)<=AH$4),AND(DATE(YEAR(AH$4),MONTH(AH$4),$AA10)>=AH$3,DATE(YEAR(AH$4),MONTH(AH$4),$AA10)<=AH$4)),'Kosten | Costs'!$D$14,0)) | AI10: =IF(N('Kosten | Costs'!$D$14)=0,0,IF(OR(AND(DATE(YEAR(AI$3),MONTH(AI$3),$AA10)>=AI$3,DATE(YEAR(AI$3),MONTH(AI$3),$AA10)<=AI$4),AND(DATE(YEAR(AI$4),MONTH(AI$4),$AA10)>=AI$3,DATE(YEAR(AI$4),MONTH(AI$4),$AA10)<=AI$4)),'Kosten | Costs'!$D$14,0)) | ... AM10: =IF(N('Kosten | Costs'!$D$14)=0,0,IF(OR(AND(DATE(YEAR(AM$3),MONTH(AM$3),$AA10)>=AM$3,DATE(YEAR(AM$3),MONTH(AM$3),$AA10)<=AM$4),AND(DATE(YEAR(AM$4),MONTH(AM$4),$AA10)>=AM$3,DATE(YEAR(AM$4),MONTH(AM$4),$AA10)<=AM$4)),'Kosten | Costs'!$D$14,0))
A11: kpi.recv | B11: Offene Forderungen | C11: Open receivables | J11: =IFERROR(INDEX('Rechnungen | Invoices'!$C$9:$C$108,MATCH(0,INDEX(COUNTIF($J$4:J10,'Rechnungen | Invoices'!$C$9:$C$108)+('Rechnungen | Invoices'!$C$9:$C$108=""),0),0)),"") | L11: 7 | M11: =M10+7 | N11: =M11+6 | O11: =SUMIFS('Rechnungen | Invoices'!$Q$9:$Q$108,'Rechnungen | Invoices'!$R$9:$R$108,">="&M11,'Rechnungen | Invoices'!$R$9:$R$108,"<="&N11) | P11: =SUMIFS('Rechnungen | Invoices'!$S$9:$S$108,'Rechnungen | Invoices'!$L$9:$L$108,">="&M11,'Rechnungen | Invoices'!$L$9:$L$108,"<="&N11) | Q11: =AH$25 | R11: =SUMIFS('Kosten | Costs'!$D$34:$D$63,'Kosten | Costs'!$E$34:$E$63,">="&M11,'Kosten | Costs'!$E$34:$E$63,"<="&N11) | S11: =IF(VATON=0,0,IF(AND(DATE(YEAR(M11),MONTH(M11),VATDAY)>=M11,DATE(YEAR(M11),MONTH(M11),VATDAY)<=N11),SUMIFS('Rechnungen | Invoices'!$P$9:$P$108,'Rechnungen | Invoices'!$H$9:$H$108,">="&DATE(YEAR(M11),MONTH(M11)-1,1),'Rechnungen | Invoices'!$H$9:$H$108,"<="&DATE(YEAR(M11),MONTH(M11),1)-1),0)+IF(AND(MONTH(M11)<>MONTH(N11),DATE(YEAR(N11),MONTH(N11),VATDAY)>=M11,DATE(YEAR(N11),MONTH(N11),VATDAY)<=N11),SUMIFS('Rechnungen | Invoices'!$P$9:$P$108,'Rechnungen | Invoices'!$H$9:$H$108,">="&DATE(YEAR(N11),MONTH(N11)-1,1),'Rechnungen | Invoices'!$H$9:$H$108,"<="&DATE(YEAR(N11),MONTH(N11),1)-1),0)) | T11: =Q11+R11+S11 | U11: =U10+O11-T11 | V11: =V10+P11-T11 | W11: =IF(V11<MINCASH,2,IF(V11<MINCASH*YELLOWF,1,0)) | X11: =MINCASH | Y11: =INDEX(Config!$B$6:$C$104,MATCH("lbl.week",Config!$A$6:$A$104,0),LANG)&" "&ISOWEEKNUM(M11) | AA11: =IF('Kosten | Costs'!$E$15="",1,MIN(28,MAX(1,'Kosten | Costs'!$E$15))) | AB11: =IF(N('Kosten | Costs'!$D$15)=0,0,IF(OR(AND(DATE(YEAR(AB$3),MONTH(AB$3),$AA11)>=AB$3,DATE(YEAR(AB$3),MONTH(AB$3),$AA11)<=AB$4),AND(DATE(YEAR(AB$4),MONTH(AB$4),$AA11)>=AB$3,DATE(YEAR(AB$4),MONTH(AB$4),$AA11)<=AB$4)),'Kosten | Costs'!$D$15,0)) | AC11: =IF(N('Kosten | Costs'!$D$15)=0,0,IF(OR(AND(DATE(YEAR(AC$3),MONTH(AC$3),$AA11)>=AC$3,DATE(YEAR(AC$3),MONTH(AC$3),$AA11)<=AC$4),AND(DATE(YEAR(AC$4),MONTH(AC$4),$AA11)>=AC$3,DATE(YEAR(AC$4),MONTH(AC$4),$AA11)<=AC$4)),'Kosten | Costs'!$D$15,0)) | AD11: =IF(N('Kosten | Costs'!$D$15)=0,0,IF(OR(AND(DATE(YEAR(AD$3),MONTH(AD$3),$AA11)>=AD$3,DATE(YEAR(AD$3),MONTH(AD$3),$AA11)<=AD$4),AND(DATE(YEAR(AD$4),MONTH(AD$4),$AA11)>=AD$3,DATE(YEAR(AD$4),MONTH(AD$4),$AA11)<=AD$4)),'Kosten | Costs'!$D$15,0)) | AE11: =IF(N('Kosten | Costs'!$D$15)=0,0,IF(OR(AND(DATE(YEAR(AE$3),MONTH(AE$3),$AA11)>=AE$3,DATE(YEAR(AE$3),MONTH(AE$3),$AA11)<=AE$4),AND(DATE(YEAR(AE$4),MONTH(AE$4),$AA11)>=AE$3,DATE(YEAR(AE$4),MONTH(AE$4),$AA11)<=AE$4)),'Kosten | Costs'!$D$15,0)) | AF11: =IF(N('Kosten | Costs'!$D$15)=0,0,IF(OR(AND(DATE(YEAR(AF$3),MONTH(AF$3),$AA11)>=AF$3,DATE(YEAR(AF$3),MONTH(AF$3),$AA11)<=AF$4),AND(DATE(YEAR(AF$4),MONTH(AF$4),$AA11)>=AF$3,DATE(YEAR(AF$4),MONTH(AF$4),$AA11)<=AF$4)),'Kosten | Costs'!$D$15,0)) | AG11: =IF(N('Kosten | Costs'!$D$15)=0,0,IF(OR(AND(DATE(YEAR(AG$3),MONTH(AG$3),$AA11)>=AG$3,DATE(YEAR(AG$3),MONTH(AG$3),$AA11)<=AG$4),AND(DATE(YEAR(AG$4),MONTH(AG$4),$AA11)>=AG$3,DATE(YEAR(AG$4),MONTH(AG$4),$AA11)<=AG$4)),'Kosten | Costs'!$D$15,0)) | AH11: =IF(N('Kosten | Costs'!$D$15)=0,0,IF(OR(AND(DATE(YEAR(AH$3),MONTH(AH$3),$AA11)>=AH$3,DATE(YEAR(AH$3),MONTH(AH$3),$AA11)<=AH$4),AND(DATE(YEAR(AH$4),MONTH(AH$4),$AA11)>=AH$3,DATE(YEAR(AH$4),MONTH(AH$4),$AA11)<=AH$4)),'Kosten | Costs'!$D$15,0)) | AI11: =IF(N('Kosten | Costs'!$D$15)=0,0,IF(OR(AND(DATE(YEAR(AI$3),MONTH(AI$3),$AA11)>=AI$3,DATE(YEAR(AI$3),MONTH(AI$3),$AA11)<=AI$4),AND(DATE(YEAR(AI$4),MONTH(AI$4),$AA11)>=AI$3,DATE(YEAR(AI$4),MONTH(AI$4),$AA11)<=AI$4)),'Kosten | Costs'!$D$15,0)) | ... AM11: =IF(N('Kosten | Costs'!$D$15)=0,0,IF(OR(AND(DATE(YEAR(AM$3),MONTH(AM$3),$AA11)>=AM$3,DATE(YEAR(AM$3),MONTH(AM$3),$AA11)<=AM$4),AND(DATE(YEAR(AM$4),MONTH(AM$4),$AA11)>=AM$3,DATE(YEAR(AM$4),MONTH(AM$4),$AA11)<=AM$4)),'Kosten | Costs'!$D$15,0))
A12: kpi.recv.sub | B12: unbezahlte Rechnungen | C12: unpaid invoices | J12: =IFERROR(INDEX('Rechnungen | Invoices'!$C$9:$C$108,MATCH(0,INDEX(COUNTIF($J$4:J11,'Rechnungen | Invoices'!$C$9:$C$108)+('Rechnungen | Invoices'!$C$9:$C$108=""),0),0)),"") | L12: 8 | M12: =M11+7 | N12: =M12+6 | O12: =SUMIFS('Rechnungen | Invoices'!$Q$9:$Q$108,'Rechnungen | Invoices'!$R$9:$R$108,">="&M12,'Rechnungen | Invoices'!$R$9:$R$108,"<="&N12) | P12: =SUMIFS('Rechnungen | Invoices'!$S$9:$S$108,'Rechnungen | Invoices'!$L$9:$L$108,">="&M12,'Rechnungen | Invoices'!$L$9:$L$108,"<="&N12) | Q12: =AI$25 | R12: =SUMIFS('Kosten | Costs'!$D$34:$D$63,'Kosten | Costs'!$E$34:$E$63,">="&M12,'Kosten | Costs'!$E$34:$E$63,"<="&N12) | S12: =IF(VATON=0,0,IF(AND(DATE(YEAR(M12),MONTH(M12),VATDAY)>=M12,DATE(YEAR(M12),MONTH(M12),VATDAY)<=N12),SUMIFS('Rechnungen | Invoices'!$P$9:$P$108,'Rechnungen | Invoices'!$H$9:$H$108,">="&DATE(YEAR(M12),MONTH(M12)-1,1),'Rechnungen | Invoices'!$H$9:$H$108,"<="&DATE(YEAR(M12),MONTH(M12),1)-1),0)+IF(AND(MONTH(M12)<>MONTH(N12),DATE(YEAR(N12),MONTH(N12),VATDAY)>=M12,DATE(YEAR(N12),MONTH(N12),VATDAY)<=N12),SUMIFS('Rechnungen | Invoices'!$P$9:$P$108,'Rechnungen | Invoices'!$H$9:$H$108,">="&DATE(YEAR(N12),MONTH(N12)-1,1),'Rechnungen | Invoices'!$H$9:$H$108,"<="&DATE(YEAR(N12),MONTH(N12),1)-1),0)) | T12: =Q12+R12+S12 | U12: =U11+O12-T12 | V12: =V11+P12-T12 | W12: =IF(V12<MINCASH,2,IF(V12<MINCASH*YELLOWF,1,0)) | X12: =MINCASH | Y12: =INDEX(Config!$B$6:$C$104,MATCH("lbl.week",Config!$A$6:$A$104,0),LANG)&" "&ISOWEEKNUM(M12) | AA12: =IF('Kosten | Costs'!$E$16="",1,MIN(28,MAX(1,'Kosten | Costs'!$E$16))) | AB12: =IF(N('Kosten | Costs'!$D$16)=0,0,IF(OR(AND(DATE(YEAR(AB$3),MONTH(AB$3),$AA12)>=AB$3,DATE(YEAR(AB$3),MONTH(AB$3),$AA12)<=AB$4),AND(DATE(YEAR(AB$4),MONTH(AB$4),$AA12)>=AB$3,DATE(YEAR(AB$4),MONTH(AB$4),$AA12)<=AB$4)),'Kosten | Costs'!$D$16,0)) | AC12: =IF(N('Kosten | Costs'!$D$16)=0,0,IF(OR(AND(DATE(YEAR(AC$3),MONTH(AC$3),$AA12)>=AC$3,DATE(YEAR(AC$3),MONTH(AC$3),$AA12)<=AC$4),AND(DATE(YEAR(AC$4),MONTH(AC$4),$AA12)>=AC$3,DATE(YEAR(AC$4),MONTH(AC$4),$AA12)<=AC$4)),'Kosten | Costs'!$D$16,0)) | AD12: =IF(N('Kosten | Costs'!$D$16)=0,0,IF(OR(AND(DATE(YEAR(AD$3),MONTH(AD$3),$AA12)>=AD$3,DATE(YEAR(AD$3),MONTH(AD$3),$AA12)<=AD$4),AND(DATE(YEAR(AD$4),MONTH(AD$4),$AA12)>=AD$3,DATE(YEAR(AD$4),MONTH(AD$4),$AA12)<=AD$4)),'Kosten | Costs'!$D$16,0)) | AE12: =IF(N('Kosten | Costs'!$D$16)=0,0,IF(OR(AND(DATE(YEAR(AE$3),MONTH(AE$3),$AA12)>=AE$3,DATE(YEAR(AE$3),MONTH(AE$3),$AA12)<=AE$4),AND(DATE(YEAR(AE$4),MONTH(AE$4),$AA12)>=AE$3,DATE(YEAR(AE$4),MONTH(AE$4),$AA12)<=AE$4)),'Kosten | Costs'!$D$16,0)) | AF12: =IF(N('Kosten | Costs'!$D$16)=0,0,IF(OR(AND(DATE(YEAR(AF$3),MONTH(AF$3),$AA12)>=AF$3,DATE(YEAR(AF$3),MONTH(AF$3),$AA12)<=AF$4),AND(DATE(YEAR(AF$4),MONTH(AF$4),$AA12)>=AF$3,DATE(YEAR(AF$4),MONTH(AF$4),$AA12)<=AF$4)),'Kosten | Costs'!$D$16,0)) | AG12: =IF(N('Kosten | Costs'!$D$16)=0,0,IF(OR(AND(DATE(YEAR(AG$3),MONTH(AG$3),$AA12)>=AG$3,DATE(YEAR(AG$3),MONTH(AG$3),$AA12)<=AG$4),AND(DATE(YEAR(AG$4),MONTH(AG$4),$AA12)>=AG$3,DATE(YEAR(AG$4),MONTH(AG$4),$AA12)<=AG$4)),'Kosten | Costs'!$D$16,0)) | AH12: =IF(N('Kosten | Costs'!$D$16)=0,0,IF(OR(AND(DATE(YEAR(AH$3),MONTH(AH$3),$AA12)>=AH$3,DATE(YEAR(AH$3),MONTH(AH$3),$AA12)<=AH$4),AND(DATE(YEAR(AH$4),MONTH(AH$4),$AA12)>=AH$3,DATE(YEAR(AH$4),MONTH(AH$4),$AA12)<=AH$4)),'Kosten | Costs'!$D$16,0)) | AI12: =IF(N('Kosten | Costs'!$D$16)=0,0,IF(OR(AND(DATE(YEAR(AI$3),MONTH(AI$3),$AA12)>=AI$3,DATE(YEAR(AI$3),MONTH(AI$3),$AA12)<=AI$4),AND(DATE(YEAR(AI$4),MONTH(AI$4),$AA12)>=AI$3,DATE(YEAR(AI$4),MONTH(AI$4),$AA12)<=AI$4)),'Kosten | Costs'!$D$16,0)) | ... AM12: =IF(N('Kosten | Costs'!$D$16)=0,0,IF(OR(AND(DATE(YEAR(AM$3),MONTH(AM$3),$AA12)>=AM$3,DATE(YEAR(AM$3),MONTH(AM$3),$AA12)<=AM$4),AND(DATE(YEAR(AM$4),MONTH(AM$4),$AA12)>=AM$3,DATE(YEAR(AM$4),MONTH(AM$4),$AA12)<=AM$4)),'Kosten | Costs'!$D$16,0))
